Workbook
Name AGC: #REF!
Name ONU: #REF!
Name TAP_OFF_04: #REF!
Name TAP_OFF_08: #REF!
Name 간선증폭기: #REF!
Name 감쇄기_SA: #REF!
Name 감쇄기_모토로라: #REF!
Name 계량기: #REF!
Name 광접속함체_RN포함: #REF!
Name 광접속함체_직선형: #REF!
Name 광케이블: #REF!
Name 구내증폭기: #REF!
Name 누전차단기: #REF!
Name 동축케이블: #REF!
Name 목록: [1]목록!$A$2:$P$2
Name 방향성결합기: #REF!
Name 상향광송신기: #REF!
Name 선로증폭기: #REF!
Name 스터브케이블: #REF!
Name 암타이밴드: #REF!
Name 연장증폭기: #REF!
Name 열수축관: #REF!
Name 옥내용_8분기기: #REF!
Name 옥내용분배기: #REF!
Name 옥외용분배기: #REF!
Name 와이어바이스: #REF!
Name 자동복구기: #REF!
Name 장비명: #REF!
Name 전기선: #REF!
Name 전력삽입기: #REF!
Name 전원공급기_PS: #REF!
Name 전원공급기_UPS: #REF!
Name 조선인류클램프: #REF!
Name 조선접속클램프: #REF!
Name 종단기: #REF!
Name 지선그립: #REF!
Name 지선밴드: #REF!
Name 커넥터: #REF!
Name 케이블행거: #REF!
Name 탭브라켓_스탠: #REF!
Name 하향등화기_모토로라: #REF!
Name 하향역등화기_SA: #REF!
Name 하향역등화기_모토로라: #REF!

Sheet 사급자재 사용내역
B1: ■ 수원운용 권역 사급자재 사용 내역
E2: 25년 자재 | G2: 26년 불량자재 (누적) | J2: 26년 자재 사용 | M2: 출 고 수 량 | AB2: 입 고 수 량 | AQ2: 불 량 자 재 ( 입 고 )
B3: 자재명 | C3: 모델명 | D3: 단위 | E3: 정상 | F3: 불량 | G3: 수리 | H3: 폐기 | I3: 불량재고 | J3: 사용 | K3: 입고 | L3: 현재고 | M3: 1월 | N3: 2월 | O3: 3월 | P3: 4월 | Q3: 5월 | R3: 6월 | S3: 7월 | T3: 8월 | U3: 9월 | V3: 10월 | W3: 11월 | X3: 12월 | Y3: 합계 | Z3: 비고 | AB3: 1월 | AC3: 2월 | AD3: 3월 | AE3: 4월 | AF3: 5월 | AG3: 6월 | AH3: 7월 | AI3: 8월 | AJ3: 9월 | AK3: 10월 | AL3: 11월 | AM3: 12월 | AN3: 합계 | AO3: 비고 | AQ3: 1월 | AR3: 2월 | AS3: 3월 | AT3: 4월 | AU3: 5월 | AV3: 6월 | AW3: 7월 | AX3: 8월 | AY3: 9월 | AZ3: 10월 | BA3: 11월 | BB3: 12월 | BC3: 합계 | BD3: 비고
B4: ONU | C4: SA - GM ONU(3PORT) DFB 1*1 | D4: EA | E4: 1 | F4: 0 | H4: 1 | I4: =(F4+BC4)-(G4+H4) -> 0 | J4: =Y4 -> 0 | K4: =AN4 -> 0 | L4: =E4-J4+K4 -> 1 | M4: =SUMIFS('센터 자재 사용내역(01월)'!G:G,'센터 자재 사용내역(01월)'!E:E,'사급자재 사용내역'!C4,'센터 자재 사용내역(01월)'!F:F,"신규")+SUMIFS('센터 자재 사용내역(01월)'!G:G,'센터 자재 사용내역(01월)'!E:E,'사급자재 사용내역'!C4,'센터 자재 사용내역(01월)'!F:F,"교체") -> 0 | N4: =SUMIFS('센터 자재 사용내역(02월)'!G:G,'센터 자재 사용내역(02월)'!E:E,'사급자재 사용내역'!C4,'센터 자재 사용내역(02월)'!F:F,"신규")+SUMIFS('센터 자재 사용내역(02월)'!G:G,'센터 자재 사용내역(02월)'!E:E,'사급자재 사용내역'!C4,'센터 자재 사용내역(02월)'!F:F,"교체") -> 0 | O4: =SUMIFS('센터 자재 사용내역(03월)'!G:G,'센터 자재 사용내역(03월)'!E:E,'사급자재 사용내역'!C4,'센터 자재 사용내역(03월)'!F:F,"신규")+SUMIFS('센터 자재 사용내역(03월)'!G:G,'센터 자재 사용내역(03월)'!E:E,'사급자재 사용내역'!C4,'센터 자재 사용내역(03월)'!F:F,"교체") -> 0 | P4: =SUMIFS('센터 자재 사용내역(04월)'!G:G,'센터 자재 사용내역(04월)'!E:E,'사급자재 사용내역'!C4,'센터 자재 사용내역(04월)'!F:F,"신규")+SUMIFS('센터 자재 사용내역(04월)'!G:G,'센터 자재 사용내역(04월)'!E:E,'사급자재 사용내역'!C4,'센터 자재 사용내역(04월)'!F:F,"교체") -> 0 | Q4: =SUMIFS('센터 자재 사용내역(05월)'!G:G,'센터 자재 사용내역(05월)'!E:E,'사급자재 사용내역'!C4,'센터 자재 사용내역(05월)'!F:F,"신규")+SUMIFS('센터 자재 사용내역(05월)'!G:G,'센터 자재 사용내역(05월)'!E:E,'사급자재 사용내역'!C4,'센터 자재 사용내역(05월)'!F:F,"교체") -> 0 | R4: =SUMIFS('센터 자재 사용내역(06월)'!G:G,'센터 자재 사용내역(06월)'!E:E,'사급자재 사용내역'!C4,'센터 자재 사용내역(06월)'!F:F,"신규")+SUMIFS('센터 자재 사용내역(06월)'!G:G,'센터 자재 사용내역(06월)'!E:E,'사급자재 사용내역'!C4,'센터 자재 사용내역(06월)'!F:F,"교체") -> 0 | S4: =SUMIFS('센터 자재 사용내역(07월)'!G:G,'센터 자재 사용내역(07월)'!E:E,'사급자재 사용내역'!C4,'센터 자재 사용내역(07월)'!F:F,"신규")+SUMIFS('센터 자재 사용내역(07월)'!G:G,'센터 자재 사용내역(07월)'!E:E,'사급자재 사용내역'!C4,'센터 자재 사용내역(07월)'!F:F,"교체") -> 0 | T4: =SUMIFS('센터 자재 사용내역(08월)'!G:G,'센터 자재 사용내역(08월)'!E:E,'사급자재 사용내역'!C4,'센터 자재 사용내역(08월)'!F:F,"신규")+SUMIFS('센터 자재 사용내역(08월)'!G:G,'센터 자재 사용내역(08월)'!E:E,'사급자재 사용내역'!C4,'센터 자재 사용내역(08월)'!F:F,"교체") -> 0 | U4: =SUMIFS('센터 자재 사용내역(09월)'!G:G,'센터 자재 사용내역(09월)'!E:E,'사급자재 사용내역'!C4,'센터 자재 사용내역(09월)'!F:F,"신규")+SUMIFS('센터 자재 사용내역(09월)'!G:G,'센터 자재 사용내역(09월)'!E:E,'사급자재 사용내역'!C4,'센터 자재 사용내역(09월)'!F:F,"교체") -> 0 | V4: =SUMIFS('센터 자재 사용내역(10월)'!G:G,'센터 자재 사용내역(10월)'!E:E,'사급자재 사용내역'!C4,'센터 자재 사용내역(10월)'!F:F,"신규")+SUMIFS('센터 자재 사용내역(10월)'!G:G,'센터 자재 사용내역(10월)'!E:E,'사급자재 사용내역'!C4,'센터 자재 사용내역(10월)'!F:F,"교체") -> 0 | W4: =SUMIFS('센터 자재 사용내역(11월)'!G:G,'센터 자재 사용내역(11월)'!E:E,'사급자재 사용내역'!C4,'센터 자재 사용내역(11월)'!F:F,"신규")+SUMIFS('센터 자재 사용내역(11월)'!G:G,'센터 자재 사용내역(11월)'!E:E,'사급자재 사용내역'!C4,'센터 자재 사용내역(11월)'!F:F,"교체") -> 0 | X4: =SUMIFS('센터 자재 사용내역(12월)'!G:G,'센터 자재 사용내역(12월)'!E:E,'사급자재 사용내역'!C4,'센터 자재 사용내역(12월)'!F:F,"신규")+SUMIFS('센터 자재 사용내역(12월)'!G:G,'센터 자재 사용내역(12월)'!E:E,'사급자재 사용내역'!C4,'센터 자재 사용내역(12월)'!F:F,"교체") -> 0 | Y4: =SUM(M4:X4) -> 0 | AN4: =SUM(AB4:AM4) -> 0 | AQ4: =SUMIFS('센터 자재 사용내역(01월)'!G:G,'센터 자재 사용내역(01월)'!E:E,'사급자재 사용내역'!C4,'센터 자재 사용내역(01월)'!F:F,"불량") -> 0 | AR4: =SUMIFS('센터 자재 사용내역(02월)'!G:G,'센터 자재 사용내역(02월)'!E:E,'사급자재 사용내역'!C4,'센터 자재 사용내역(02월)'!F:F,"불량") -> 0 | AS4: =SUMIFS('센터 자재 사용내역(03월)'!G:G,'센터 자재 사용내역(03월)'!E:E,'사급자재 사용내역'!C4,'센터 자재 사용내역(03월)'!F:F,"불량") -> 0 | AT4: =SUMIFS('센터 자재 사용내역(04월)'!G:G,'센터 자재 사용내역(04월)'!E:E,'사급자재 사용내역'!C4,'센터 자재 사용내역(04월)'!F:F,"불량") -> 0 | AU4: =SUMIFS('센터 자재 사용내역(05월)'!G:G,'센터 자재 사용내역(05월)'!E:E,'사급자재 사용내역'!C4,'센터 자재 사용내역(05월)'!F:F,"불량") -> 1 | AV4: =SUMIFS('센터 자재 사용내역(06월)'!G:G,'센터 자재 사용내역(06월)'!E:E,'사급자재 사용내역'!C4,'센터 자재 사용내역(06월)'!F:F,"불량") -> 0 | AW4: =SUMIFS('센터 자재 사용내역(07월)'!G:G,'센터 자재 사용내역(07월)'!E:E,'사급자재 사용내역'!C4,'센터 자재 사용내역(07월)'!F:F,"불량") -> 0 | AX4: =SUMIFS('센터 자재 사용내역(08월)'!G:G,'센터 자재 사용내역(08월)'!E:E,'사급자재 사용내역'!C4,'센터 자재 사용내역(08월)'!F:F,"불량") -> 0 | AY4: =SUMIFS('센터 자재 사용내역(09월)'!G:G,'센터 자재 사용내역(09월)'!E:E,'사급자재 사용내역'!C4,'센터 자재 사용내역(09월)'!F:F,"불량") -> 0 | AZ4: =SUMIFS('센터 자재 사용내역(10월)'!G:G,'센터 자재 사용내역(10월)'!E:E,'사급자재 사용내역'!C4,'센터 자재 사용내역(10월)'!F:F,"불량") -> 0 | BA4: =SUMIFS('센터 자재 사용내역(11월)'!G:G,'센터 자재 사용내역(11월)'!E:E,'사급자재 사용내역'!C4,'센터 자재 사용내역(11월)'!F:F,"불량") -> 0 | BB4: =SUMIFS('센터 자재 사용내역(12월)'!G:G,'센터 자재 사용내역(12월)'!E:E,'사급자재 사용내역'!C4,'센터 자재 사용내역(12월)'!F:F,"불량") -> 0 | BC4: =SUM(AQ4:BB4) -> 1
C5: SA - GS-7000 DFB 1*1 | D5: EA | E5: 1 | F5: 2 | G5: 1 | H5: 3 | I5: =(F5+BC5)-(G5+H5) -> 0 | J5: =Y5 -> 0 | K5: =AN5 -> 1 | L5: =E5-J5+K5 -> 2 | M5: =SUMIFS('센터 자재 사용내역(01월)'!G:G,'센터 자재 사용내역(01월)'!E:E,'사급자재 사용내역'!C5,'센터 자재 사용내역(01월)'!F:F,"신규")+SUMIFS('센터 자재 사용내역(01월)'!G:G,'센터 자재 사용내역(01월)'!E:E,'사급자재 사용내역'!C5,'센터 자재 사용내역(01월)'!F:F,"교체") -> 0 | N5: =SUMIFS('센터 자재 사용내역(02월)'!G:G,'센터 자재 사용내역(02월)'!E:E,'사급자재 사용내역'!C5,'센터 자재 사용내역(02월)'!F:F,"신규")+SUMIFS('센터 자재 사용내역(02월)'!G:G,'센터 자재 사용내역(02월)'!E:E,'사급자재 사용내역'!C5,'센터 자재 사용내역(02월)'!F:F,"교체") -> 0 | O5: =SUMIFS('센터 자재 사용내역(03월)'!G:G,'센터 자재 사용내역(03월)'!E:E,'사급자재 사용내역'!C5,'센터 자재 사용내역(03월)'!F:F,"신규")+SUMIFS('센터 자재 사용내역(03월)'!G:G,'센터 자재 사용내역(03월)'!E:E,'사급자재 사용내역'!C5,'센터 자재 사용내역(03월)'!F:F,"교체") -> 0 | P5: =SUMIFS('센터 자재 사용내역(04월)'!G:G,'센터 자재 사용내역(04월)'!E:E,'사급자재 사용내역'!C5,'센터 자재 사용내역(04월)'!F:F,"신규")+SUMIFS('센터 자재 사용내역(04월)'!G:G,'센터 자재 사용내역(04월)'!E:E,'사급자재 사용내역'!C5,'센터 자재 사용내역(04월)'!F:F,"교체") -> 0 | Q5: =SUMIFS('센터 자재 사용내역(05월)'!G:G,'센터 자재 사용내역(05월)'!E:E,'사급자재 사용내역'!C5,'센터 자재 사용내역(05월)'!F:F,"신규")+SUMIFS('센터 자재 사용내역(05월)'!G:G,'센터 자재 사용내역(05월)'!E:E,'사급자재 사용내역'!C5,'센터 자재 사용내역(05월)'!F:F,"교체") -> 0 | R5: =SUMIFS('센터 자재 사용내역(06월)'!G:G,'센터 자재 사용내역(06월)'!E:E,'사급자재 사용내역'!C5,'센터 자재 사용내역(06월)'!F:F,"신규")+SUMIFS('센터 자재 사용내역(06월)'!G:G,'센터 자재 사용내역(06월)'!E:E,'사급자재 사용내역'!C5,'센터 자재 사용내역(06월)'!F:F,"교체") -> 0 | S5: =SUMIFS('센터 자재 사용내역(07월)'!G:G,'센터 자재 사용내역(07월)'!E:E,'사급자재 사용내역'!C5,'센터 자재 사용내역(07월)'!F:F,"신규")+SUMIFS('센터 자재 사용내역(07월)'!G:G,'센터 자재 사용내역(07월)'!E:E,'사급자재 사용내역'!C5,'센터 자재 사용내역(07월)'!F:F,"교체") -> 0 | T5: =SUMIFS('센터 자재 사용내역(08월)'!G:G,'센터 자재 사용내역(08월)'!E:E,'사급자재 사용내역'!C5,'센터 자재 사용내역(08월)'!F:F,"신규")+SUMIFS('센터 자재 사용내역(08월)'!G:G,'센터 자재 사용내역(08월)'!E:E,'사급자재 사용내역'!C5,'센터 자재 사용내역(08월)'!F:F,"교체") -> 0 | U5: =SUMIFS('센터 자재 사용내역(09월)'!G:G,'센터 자재 사용내역(09월)'!E:E,'사급자재 사용내역'!C5,'센터 자재 사용내역(09월)'!F:F,"신규")+SUMIFS('센터 자재 사용내역(09월)'!G:G,'센터 자재 사용내역(09월)'!E:E,'사급자재 사용내역'!C5,'센터 자재 사용내역(09월)'!F:F,"교체") -> 0 | V5: =SUMIFS('센터 자재 사용내역(10월)'!G:G,'센터 자재 사용내역(10월)'!E:E,'사급자재 사용내역'!C5,'센터 자재 사용내역(10월)'!F:F,"신규")+SUMIFS('센터 자재 사용내역(10월)'!G:G,'센터 자재 사용내역(10월)'!E:E,'사급자재 사용내역'!C5,'센터 자재 사용내역(10월)'!F:F,"교체") -> 0 | W5: =SUMIFS('센터 자재 사용내역(11월)'!G:G,'센터 자재 사용내역(11월)'!E:E,'사급자재 사용내역'!C5,'센터 자재 사용내역(11월)'!F:F,"신규")+SUMIFS('센터 자재 사용내역(11월)'!G:G,'센터 자재 사용내역(11월)'!E:E,'사급자재 사용내역'!C5,'센터 자재 사용내역(11월)'!F:F,"교체") -> 0 | X5: =SUMIFS('센터 자재 사용내역(12월)'!G:G,'센터 자재 사용내역(12월)'!E:E,'사급자재 사용내역'!C5,'센터 자재 사용내역(12월)'!F:F,"신규")+SUMIFS('센터 자재 사용내역(12월)'!G:G,'센터 자재 사용내역(12월)'!E:E,'사급자재 사용내역'!C5,'센터 자재 사용내역(12월)'!F:F,"교체") -> 0 | Y5: =SUM(M5:X5) -> 0 | AC5: 1 | AN5: =SUM(AB5:AM5) -> 1 | AQ5: =SUMIFS('센터 자재 사용내역(01월)'!G:G,'센터 자재 사용내역(01월)'!E:E,'사급자재 사용내역'!C5,'센터 자재 사용내역(01월)'!F:F,"불량") -> 0 | AR5: =SUMIFS('센터 자재 사용내역(02월)'!G:G,'센터 자재 사용내역(02월)'!E:E,'사급자재 사용내역'!C5,'센터 자재 사용내역(02월)'!F:F,"불량") -> 1 | AS5: =SUMIFS('센터 자재 사용내역(03월)'!G:G,'센터 자재 사용내역(03월)'!E:E,'사급자재 사용내역'!C5,'센터 자재 사용내역(03월)'!F:F,"불량") -> 1 | AT5: =SUMIFS('센터 자재 사용내역(04월)'!G:G,'센터 자재 사용내역(04월)'!E:E,'사급자재 사용내역'!C5,'센터 자재 사용내역(04월)'!F:F,"불량") -> 0 | AU5: =SUMIFS('센터 자재 사용내역(05월)'!G:G,'센터 자재 사용내역(05월)'!E:E,'사급자재 사용내역'!C5,'센터 자재 사용내역(05월)'!F:F,"불량") -> 0 | AV5: =SUMIFS('센터 자재 사용내역(06월)'!G:G,'센터 자재 사용내역(06월)'!E:E,'사급자재 사용내역'!C5,'센터 자재 사용내역(06월)'!F:F,"불량") -> 0 | AW5: =SUMIFS('센터 자재 사용내역(07월)'!G:G,'센터 자재 사용내역(07월)'!E:E,'사급자재 사용내역'!C5,'센터 자재 사용내역(07월)'!F:F,"불량") -> 0 | AX5: =SUMIFS('센터 자재 사용내역(08월)'!G:G,'센터 자재 사용내역(08월)'!E:E,'사급자재 사용내역'!C5,'센터 자재 사용내역(08월)'!F:F,"불량") -> 0 | AY5: =SUMIFS('센터 자재 사용내역(09월)'!G:G,'센터 자재 사용내역(09월)'!E:E,'사급자재 사용내역'!C5,'센터 자재 사용내역(09월)'!F:F,"불량") -> 0 | AZ5: =SUMIFS('센터 자재 사용내역(10월)'!G:G,'센터 자재 사용내역(10월)'!E:E,'사급자재 사용내역'!C5,'센터 자재 사용내역(10월)'!F:F,"불량") -> 0 | BA5: =SUMIFS('센터 자재 사용내역(11월)'!G:G,'센터 자재 사용내역(11월)'!E:E,'사급자재 사용내역'!C5,'센터 자재 사용내역(11월)'!F:F,"불량") -> 0 | BB5: =SUMIFS('센터 자재 사용내역(12월)'!G:G,'센터 자재 사용내역(12월)'!E:E,'사급자재 사용내역'!C5,'센터 자재 사용내역(12월)'!F:F,"불량") -> 0 | BC5: =SUM(AQ5:BB5) -> 2
C6: SA - GS-7000 DFB 2*2 | D6: EA | E6: 0 | F6: 0 | I6: =(F6+BC6)-(G6+H6) -> 0 | J6: =Y6 -> 0 | K6: =AN6 -> 0 | L6: =E6-J6+K6 -> 0 | M6: =SUMIFS('센터 자재 사용내역(01월)'!G:G,'센터 자재 사용내역(01월)'!E:E,'사급자재 사용내역'!C6,'센터 자재 사용내역(01월)'!F:F,"신규")+SUMIFS('센터 자재 사용내역(01월)'!G:G,'센터 자재 사용내역(01월)'!E:E,'사급자재 사용내역'!C6,'센터 자재 사용내역(01월)'!F:F,"교체") -> 0 | N6: =SUMIFS('센터 자재 사용내역(02월)'!G:G,'센터 자재 사용내역(02월)'!E:E,'사급자재 사용내역'!C6,'센터 자재 사용내역(02월)'!F:F,"신규")+SUMIFS('센터 자재 사용내역(02월)'!G:G,'센터 자재 사용내역(02월)'!E:E,'사급자재 사용내역'!C6,'센터 자재 사용내역(02월)'!F:F,"교체") -> 0 | O6: =SUMIFS('센터 자재 사용내역(03월)'!G:G,'센터 자재 사용내역(03월)'!E:E,'사급자재 사용내역'!C6,'센터 자재 사용내역(03월)'!F:F,"신규")+SUMIFS('센터 자재 사용내역(03월)'!G:G,'센터 자재 사용내역(03월)'!E:E,'사급자재 사용내역'!C6,'센터 자재 사용내역(03월)'!F:F,"교체") -> 0 | P6: =SUMIFS('센터 자재 사용내역(04월)'!G:G,'센터 자재 사용내역(04월)'!E:E,'사급자재 사용내역'!C6,'센터 자재 사용내역(04월)'!F:F,"신규")+SUMIFS('센터 자재 사용내역(04월)'!G:G,'센터 자재 사용내역(04월)'!E:E,'사급자재 사용내역'!C6,'센터 자재 사용내역(04월)'!F:F,"교체") -> 0 | Q6: =SUMIFS('센터 자재 사용내역(05월)'!G:G,'센터 자재 사용내역(05월)'!E:E,'사급자재 사용내역'!C6,'센터 자재 사용내역(05월)'!F:F,"신규")+SUMIFS('센터 자재 사용내역(05월)'!G:G,'센터 자재 사용내역(05월)'!E:E,'사급자재 사용내역'!C6,'센터 자재 사용내역(05월)'!F:F,"교체") -> 0 | R6: =SUMIFS('센터 자재 사용내역(06월)'!G:G,'센터 자재 사용내역(06월)'!E:E,'사급자재 사용내역'!C6,'센터 자재 사용내역(06월)'!F:F,"신규")+SUMIFS('센터 자재 사용내역(06월)'!G:G,'센터 자재 사용내역(06월)'!E:E,'사급자재 사용내역'!C6,'센터 자재 사용내역(06월)'!F:F,"교체") -> 0 | S6: =SUMIFS('센터 자재 사용내역(07월)'!G:G,'센터 자재 사용내역(07월)'!E:E,'사급자재 사용내역'!C6,'센터 자재 사용내역(07월)'!F:F,"신규")+SUMIFS('센터 자재 사용내역(07월)'!G:G,'센터 자재 사용내역(07월)'!E:E,'사급자재 사용내역'!C6,'센터 자재 사용내역(07월)'!F:F,"교체") -> 0 | T6: =SUMIFS('센터 자재 사용내역(08월)'!G:G,'센터 자재 사용내역(08월)'!E:E,'사급자재 사용내역'!C6,'센터 자재 사용내역(08월)'!F:F,"신규")+SUMIFS('센터 자재 사용내역(08월)'!G:G,'센터 자재 사용내역(08월)'!E:E,'사급자재 사용내역'!C6,'센터 자재 사용내역(08월)'!F:F,"교체") -> 0 | U6: =SUMIFS('센터 자재 사용내역(09월)'!G:G,'센터 자재 사용내역(09월)'!E:E,'사급자재 사용내역'!C6,'센터 자재 사용내역(09월)'!F:F,"신규")+SUMIFS('센터 자재 사용내역(09월)'!G:G,'센터 자재 사용내역(09월)'!E:E,'사급자재 사용내역'!C6,'센터 자재 사용내역(09월)'!F:F,"교체") -> 0 | V6: =SUMIFS('센터 자재 사용내역(10월)'!G:G,'센터 자재 사용내역(10월)'!E:E,'사급자재 사용내역'!C6,'센터 자재 사용내역(10월)'!F:F,"신규")+SUMIFS('센터 자재 사용내역(10월)'!G:G,'센터 자재 사용내역(10월)'!E:E,'사급자재 사용내역'!C6,'센터 자재 사용내역(10월)'!F:F,"교체") -> 0 | W6: =SUMIFS('센터 자재 사용내역(11월)'!G:G,'센터 자재 사용내역(11월)'!E:E,'사급자재 사용내역'!C6,'센터 자재 사용내역(11월)'!F:F,"신규")+SUMIFS('센터 자재 사용내역(11월)'!G:G,'센터 자재 사용내역(11월)'!E:E,'사급자재 사용내역'!C6,'센터 자재 사용내역(11월)'!F:F,"교체") -> 0 | X6: =SUMIFS('센터 자재 사용내역(12월)'!G:G,'센터 자재 사용내역(12월)'!E:E,'사급자재 사용내역'!C6,'센터 자재 사용내역(12월)'!F:F,"신규")+SUMIFS('센터 자재 사용내역(12월)'!G:G,'센터 자재 사용내역(12월)'!E:E,'사급자재 사용내역'!C6,'센터 자재 사용내역(12월)'!F:F,"교체") -> 0 | Y6: =SUM(M6:X6) -> 0 | AN6: =SUM(AB6:AM6) -> 0 | AQ6: =SUMIFS('센터 자재 사용내역(01월)'!G:G,'센터 자재 사용내역(01월)'!E:E,'사급자재 사용내역'!C6,'센터 자재 사용내역(01월)'!F:F,"불량") -> 0 | AR6: =SUMIFS('센터 자재 사용내역(02월)'!G:G,'센터 자재 사용내역(02월)'!E:E,'사급자재 사용내역'!C6,'센터 자재 사용내역(02월)'!F:F,"불량") -> 0 | AS6: =SUMIFS('센터 자재 사용내역(03월)'!G:G,'센터 자재 사용내역(03월)'!E:E,'사급자재 사용내역'!C6,'센터 자재 사용내역(03월)'!F:F,"불량") -> 0 | AT6: =SUMIFS('센터 자재 사용내역(04월)'!G:G,'센터 자재 사용내역(04월)'!E:E,'사급자재 사용내역'!C6,'센터 자재 사용내역(04월)'!F:F,"불량") -> 0 | AU6: =SUMIFS('센터 자재 사용내역(05월)'!G:G,'센터 자재 사용내역(05월)'!E:E,'사급자재 사용내역'!C6,'센터 자재 사용내역(05월)'!F:F,"불량") -> 0 | AV6: =SUMIFS('센터 자재 사용내역(06월)'!G:G,'센터 자재 사용내역(06월)'!E:E,'사급자재 사용내역'!C6,'센터 자재 사용내역(06월)'!F:F,"불량") -> 0 | AW6: =SUMIFS('센터 자재 사용내역(07월)'!G:G,'센터 자재 사용내역(07월)'!E:E,'사급자재 사용내역'!C6,'센터 자재 사용내역(07월)'!F:F,"불량") -> 0 | AX6: =SUMIFS('센터 자재 사용내역(08월)'!G:G,'센터 자재 사용내역(08월)'!E:E,'사급자재 사용내역'!C6,'센터 자재 사용내역(08월)'!F:F,"불량") -> 0 | AY6: =SUMIFS('센터 자재 사용내역(09월)'!G:G,'센터 자재 사용내역(09월)'!E:E,'사급자재 사용내역'!C6,'센터 자재 사용내역(09월)'!F:F,"불량") -> 0 | AZ6: =SUMIFS('센터 자재 사용내역(10월)'!G:G,'센터 자재 사용내역(10월)'!E:E,'사급자재 사용내역'!C6,'센터 자재 사용내역(10월)'!F:F,"불량") -> 0 | BA6: =SUMIFS('센터 자재 사용내역(11월)'!G:G,'센터 자재 사용내역(11월)'!E:E,'사급자재 사용내역'!C6,'센터 자재 사용내역(11월)'!F:F,"불량") -> 0 | BB6: =SUMIFS('센터 자재 사용내역(12월)'!G:G,'센터 자재 사용내역(12월)'!E:E,'사급자재 사용내역'!C6,'센터 자재 사용내역(12월)'!F:F,"불량") -> 0 | BC6: =SUM(AQ6:BB6) -> 0
C7: 하모닉 - HLN3142-42-AS | D7: EA | E7: 1 | F7: 0 | I7: =(F7+BC7)-(G7+H7) -> 0 | J7: =Y7 -> 0 | K7: =AN7 -> 0 | L7: =E7-J7+K7 -> 1 | M7: =SUMIFS('센터 자재 사용내역(01월)'!G:G,'센터 자재 사용내역(01월)'!E:E,'사급자재 사용내역'!C7,'센터 자재 사용내역(01월)'!F:F,"신규")+SUMIFS('센터 자재 사용내역(01월)'!G:G,'센터 자재 사용내역(01월)'!E:E,'사급자재 사용내역'!C7,'센터 자재 사용내역(01월)'!F:F,"교체") -> 0 | N7: =SUMIFS('센터 자재 사용내역(02월)'!G:G,'센터 자재 사용내역(02월)'!E:E,'사급자재 사용내역'!C7,'센터 자재 사용내역(02월)'!F:F,"신규")+SUMIFS('센터 자재 사용내역(02월)'!G:G,'센터 자재 사용내역(02월)'!E:E,'사급자재 사용내역'!C7,'센터 자재 사용내역(02월)'!F:F,"교체") -> 0 | O7: =SUMIFS('센터 자재 사용내역(03월)'!G:G,'센터 자재 사용내역(03월)'!E:E,'사급자재 사용내역'!C7,'센터 자재 사용내역(03월)'!F:F,"신규")+SUMIFS('센터 자재 사용내역(03월)'!G:G,'센터 자재 사용내역(03월)'!E:E,'사급자재 사용내역'!C7,'센터 자재 사용내역(03월)'!F:F,"교체") -> 0 | P7: =SUMIFS('센터 자재 사용내역(04월)'!G:G,'센터 자재 사용내역(04월)'!E:E,'사급자재 사용내역'!C7,'센터 자재 사용내역(04월)'!F:F,"신규")+SUMIFS('센터 자재 사용내역(04월)'!G:G,'센터 자재 사용내역(04월)'!E:E,'사급자재 사용내역'!C7,'센터 자재 사용내역(04월)'!F:F,"교체") -> 0 | Q7: =SUMIFS('센터 자재 사용내역(05월)'!G:G,'센터 자재 사용내역(05월)'!E:E,'사급자재 사용내역'!C7,'센터 자재 사용내역(05월)'!F:F,"신규")+SUMIFS('센터 자재 사용내역(05월)'!G:G,'센터 자재 사용내역(05월)'!E:E,'사급자재 사용내역'!C7,'센터 자재 사용내역(05월)'!F:F,"교체") -> 0 | R7: =SUMIFS('센터 자재 사용내역(06월)'!G:G,'센터 자재 사용내역(06월)'!E:E,'사급자재 사용내역'!C7,'센터 자재 사용내역(06월)'!F:F,"신규")+SUMIFS('센터 자재 사용내역(06월)'!G:G,'센터 자재 사용내역(06월)'!E:E,'사급자재 사용내역'!C7,'센터 자재 사용내역(06월)'!F:F,"교체") -> 0 | S7: =SUMIFS('센터 자재 사용내역(07월)'!G:G,'센터 자재 사용내역(07월)'!E:E,'사급자재 사용내역'!C7,'센터 자재 사용내역(07월)'!F:F,"신규")+SUMIFS('센터 자재 사용내역(07월)'!G:G,'센터 자재 사용내역(07월)'!E:E,'사급자재 사용내역'!C7,'센터 자재 사용내역(07월)'!F:F,"교체") -> 0 | T7: =SUMIFS('센터 자재 사용내역(08월)'!G:G,'센터 자재 사용내역(08월)'!E:E,'사급자재 사용내역'!C7,'센터 자재 사용내역(08월)'!F:F,"신규")+SUMIFS('센터 자재 사용내역(08월)'!G:G,'센터 자재 사용내역(08월)'!E:E,'사급자재 사용내역'!C7,'센터 자재 사용내역(08월)'!F:F,"교체") -> 0 | U7: =SUMIFS('센터 자재 사용내역(09월)'!G:G,'센터 자재 사용내역(09월)'!E:E,'사급자재 사용내역'!C7,'센터 자재 사용내역(09월)'!F:F,"신규")+SUMIFS('센터 자재 사용내역(09월)'!G:G,'센터 자재 사용내역(09월)'!E:E,'사급자재 사용내역'!C7,'센터 자재 사용내역(09월)'!F:F,"교체") -> 0 | V7: =SUMIFS('센터 자재 사용내역(10월)'!G:G,'센터 자재 사용내역(10월)'!E:E,'사급자재 사용내역'!C7,'센터 자재 사용내역(10월)'!F:F,"신규")+SUMIFS('센터 자재 사용내역(10월)'!G:G,'센터 자재 사용내역(10월)'!E:E,'사급자재 사용내역'!C7,'센터 자재 사용내역(10월)'!F:F,"교체") -> 0 | W7: =SUMIFS('센터 자재 사용내역(11월)'!G:G,'센터 자재 사용내역(11월)'!E:E,'사급자재 사용내역'!C7,'센터 자재 사용내역(11월)'!F:F,"신규")+SUMIFS('센터 자재 사용내역(11월)'!G:G,'센터 자재 사용내역(11월)'!E:E,'사급자재 사용내역'!C7,'센터 자재 사용내역(11월)'!F:F,"교체") -> 0 | X7: =SUMIFS('센터 자재 사용내역(12월)'!G:G,'센터 자재 사용내역(12월)'!E:E,'사급자재 사용내역'!C7,'센터 자재 사용내역(12월)'!F:F,"신규")+SUMIFS('센터 자재 사용내역(12월)'!G:G,'센터 자재 사용내역(12월)'!E:E,'사급자재 사용내역'!C7,'센터 자재 사용내역(12월)'!F:F,"교체") -> 0 | Y7: =SUM(M7:X7) -> 0 | AN7: =SUM(AB7:AM7) -> 0 | AQ7: =SUMIFS('센터 자재 사용내역(01월)'!G:G,'센터 자재 사용내역(01월)'!E:E,'사급자재 사용내역'!C7,'센터 자재 사용내역(01월)'!F:F,"불량") -> 0 | AR7: =SUMIFS('센터 자재 사용내역(02월)'!G:G,'센터 자재 사용내역(02월)'!E:E,'사급자재 사용내역'!C7,'센터 자재 사용내역(02월)'!F:F,"불량") -> 0 | AS7: =SUMIFS('센터 자재 사용내역(03월)'!G:G,'센터 자재 사용내역(03월)'!E:E,'사급자재 사용내역'!C7,'센터 자재 사용내역(03월)'!F:F,"불량") -> 0 | AT7: =SUMIFS('센터 자재 사용내역(04월)'!G:G,'센터 자재 사용내역(04월)'!E:E,'사급자재 사용내역'!C7,'센터 자재 사용내역(04월)'!F:F,"불량") -> 0 | AU7: =SUMIFS('센터 자재 사용내역(05월)'!G:G,'센터 자재 사용내역(05월)'!E:E,'사급자재 사용내역'!C7,'센터 자재 사용내역(05월)'!F:F,"불량") -> 0 | AV7: =SUMIFS('센터 자재 사용내역(06월)'!G:G,'센터 자재 사용내역(06월)'!E:E,'사급자재 사용내역'!C7,'센터 자재 사용내역(06월)'!F:F,"불량") -> 0 | AW7: =SUMIFS('센터 자재 사용내역(07월)'!G:G,'센터 자재 사용내역(07월)'!E:E,'사급자재 사용내역'!C7,'센터 자재 사용내역(07월)'!F:F,"불량") -> 0 | AX7: =SUMIFS('센터 자재 사용내역(08월)'!G:G,'센터 자재 사용내역(08월)'!E:E,'사급자재 사용내역'!C7,'센터 자재 사용내역(08월)'!F:F,"불량") -> 0 | AY7: =SUMIFS('센터 자재 사용내역(09월)'!G:G,'센터 자재 사용내역(09월)'!E:E,'사급자재 사용내역'!C7,'센터 자재 사용내역(09월)'!F:F,"불량") -> 0 | AZ7: =SUMIFS('센터 자재 사용내역(10월)'!G:G,'센터 자재 사용내역(10월)'!E:E,'사급자재 사용내역'!C7,'센터 자재 사용내역(10월)'!F:F,"불량") -> 0 | BA7: =SUMIFS('센터 자재 사용내역(11월)'!G:G,'센터 자재 사용내역(11월)'!E:E,'사급자재 사용내역'!C7,'센터 자재 사용내역(11월)'!F:F,"불량") -> 0 | BB7: =SUMIFS('센터 자재 사용내역(12월)'!G:G,'센터 자재 사용내역(12월)'!E:E,'사급자재 사용내역'!C7,'센터 자재 사용내역(12월)'!F:F,"불량") -> 0 | BC7: =SUM(AQ7:BB7) -> 0
C8: 하모닉 - HLN3144-AS | D8: EA | E8: 4 | F8: 0 | I8: =(F8+BC8)-(G8+H8) -> 1 | J8: =Y8 -> 1 | K8: =AN8 -> 0 | L8: =E8-J8+K8 -> 3 | M8: =SUMIFS('센터 자재 사용내역(01월)'!G:G,'센터 자재 사용내역(01월)'!E:E,'사급자재 사용내역'!C8,'센터 자재 사용내역(01월)'!F:F,"신규")+SUMIFS('센터 자재 사용내역(01월)'!G:G,'센터 자재 사용내역(01월)'!E:E,'사급자재 사용내역'!C8,'센터 자재 사용내역(01월)'!F:F,"교체") -> 0 | N8: =SUMIFS('센터 자재 사용내역(02월)'!G:G,'센터 자재 사용내역(02월)'!E:E,'사급자재 사용내역'!C8,'센터 자재 사용내역(02월)'!F:F,"신규")+SUMIFS('센터 자재 사용내역(02월)'!G:G,'센터 자재 사용내역(02월)'!E:E,'사급자재 사용내역'!C8,'센터 자재 사용내역(02월)'!F:F,"교체") -> 0 | O8: =SUMIFS('센터 자재 사용내역(03월)'!G:G,'센터 자재 사용내역(03월)'!E:E,'사급자재 사용내역'!C8,'센터 자재 사용내역(03월)'!F:F,"신규")+SUMIFS('센터 자재 사용내역(03월)'!G:G,'센터 자재 사용내역(03월)'!E:E,'사급자재 사용내역'!C8,'센터 자재 사용내역(03월)'!F:F,"교체") -> 0 | P8: =SUMIFS('센터 자재 사용내역(04월)'!G:G,'센터 자재 사용내역(04월)'!E:E,'사급자재 사용내역'!C8,'센터 자재 사용내역(04월)'!F:F,"신규")+SUMIFS('센터 자재 사용내역(04월)'!G:G,'센터 자재 사용내역(04월)'!E:E,'사급자재 사용내역'!C8,'센터 자재 사용내역(04월)'!F:F,"교체") -> 0 | Q8: =SUMIFS('센터 자재 사용내역(05월)'!G:G,'센터 자재 사용내역(05월)'!E:E,'사급자재 사용내역'!C8,'센터 자재 사용내역(05월)'!F:F,"신규")+SUMIFS('센터 자재 사용내역(05월)'!G:G,'센터 자재 사용내역(05월)'!E:E,'사급자재 사용내역'!C8,'센터 자재 사용내역(05월)'!F:F,"교체") -> 0 | R8: =SUMIFS('센터 자재 사용내역(06월)'!G:G,'센터 자재 사용내역(06월)'!E:E,'사급자재 사용내역'!C8,'센터 자재 사용내역(06월)'!F:F,"신규")+SUMIFS('센터 자재 사용내역(06월)'!G:G,'센터 자재 사용내역(06월)'!E:E,'사급자재 사용내역'!C8,'센터 자재 사용내역(06월)'!F:F,"교체") -> 0 | S8: =SUMIFS('센터 자재 사용내역(07월)'!G:G,'센터 자재 사용내역(07월)'!E:E,'사급자재 사용내역'!C8,'센터 자재 사용내역(07월)'!F:F,"신규")+SUMIFS('센터 자재 사용내역(07월)'!G:G,'센터 자재 사용내역(07월)'!E:E,'사급자재 사용내역'!C8,'센터 자재 사용내역(07월)'!F:F,"교체") -> 1 | T8: =SUMIFS('센터 자재 사용내역(08월)'!G:G,'센터 자재 사용내역(08월)'!E:E,'사급자재 사용내역'!C8,'센터 자재 사용내역(08월)'!F:F,"신규")+SUMIFS('센터 자재 사용내역(08월)'!G:G,'센터 자재 사용내역(08월)'!E:E,'사급자재 사용내역'!C8,'센터 자재 사용내역(08월)'!F:F,"교체") -> 0 | U8: =SUMIFS('센터 자재 사용내역(09월)'!G:G,'센터 자재 사용내역(09월)'!E:E,'사급자재 사용내역'!C8,'센터 자재 사용내역(09월)'!F:F,"신규")+SUMIFS('센터 자재 사용내역(09월)'!G:G,'센터 자재 사용내역(09월)'!E:E,'사급자재 사용내역'!C8,'센터 자재 사용내역(09월)'!F:F,"교체") -> 0 | V8: =SUMIFS('센터 자재 사용내역(10월)'!G:G,'센터 자재 사용내역(10월)'!E:E,'사급자재 사용내역'!C8,'센터 자재 사용내역(10월)'!F:F,"신규")+SUMIFS('센터 자재 사용내역(10월)'!G:G,'센터 자재 사용내역(10월)'!E:E,'사급자재 사용내역'!C8,'센터 자재 사용내역(10월)'!F:F,"교체") -> 0 | W8: =SUMIFS('센터 자재 사용내역(11월)'!G:G,'센터 자재 사용내역(11월)'!E:E,'사급자재 사용내역'!C8,'센터 자재 사용내역(11월)'!F:F,"신규")+SUMIFS('센터 자재 사용내역(11월)'!G:G,'센터 자재 사용내역(11월)'!E:E,'사급자재 사용내역'!C8,'센터 자재 사용내역(11월)'!F:F,"교체") -> 0 | X8: =SUMIFS('센터 자재 사용내역(12월)'!G:G,'센터 자재 사용내역(12월)'!E:E,'사급자재 사용내역'!C8,'센터 자재 사용내역(12월)'!F:F,"신규")+SUMIFS('센터 자재 사용내역(12월)'!G:G,'센터 자재 사용내역(12월)'!E:E,'사급자재 사용내역'!C8,'센터 자재 사용내역(12월)'!F:F,"교체") -> 0 | Y8: =SUM(M8:X8) -> 1 | AN8: =SUM(AB8:AM8) -> 0 | AQ8: =SUMIFS('센터 자재 사용내역(01월)'!G:G,'센터 자재 사용내역(01월)'!E:E,'사급자재 사용내역'!C8,'센터 자재 사용내역(01월)'!F:F,"불량") -> 0 | AR8: =SUMIFS('센터 자재 사용내역(02월)'!G:G,'센터 자재 사용내역(02월)'!E:E,'사급자재 사용내역'!C8,'센터 자재 사용내역(02월)'!F:F,"불량") -> 0 | AS8: =SUMIFS('센터 자재 사용내역(03월)'!G:G,'센터 자재 사용내역(03월)'!E:E,'사급자재 사용내역'!C8,'센터 자재 사용내역(03월)'!F:F,"불량") -> 0 | AT8: =SUMIFS('센터 자재 사용내역(04월)'!G:G,'센터 자재 사용내역(04월)'!E:E,'사급자재 사용내역'!C8,'센터 자재 사용내역(04월)'!F:F,"불량") -> 0 | AU8: =SUMIFS('센터 자재 사용내역(05월)'!G:G,'센터 자재 사용내역(05월)'!E:E,'사급자재 사용내역'!C8,'센터 자재 사용내역(05월)'!F:F,"불량") -> 0 | AV8: =SUMIFS('센터 자재 사용내역(06월)'!G:G,'센터 자재 사용내역(06월)'!E:E,'사급자재 사용내역'!C8,'센터 자재 사용내역(06월)'!F:F,"불량") -> 0 | AW8: =SUMIFS('센터 자재 사용내역(07월)'!G:G,'센터 자재 사용내역(07월)'!E:E,'사급자재 사용내역'!C8,'센터 자재 사용내역(07월)'!F:F,"불량") -> 1 | AX8: =SUMIFS('센터 자재 사용내역(08월)'!G:G,'센터 자재 사용내역(08월)'!E:E,'사급자재 사용내역'!C8,'센터 자재 사용내역(08월)'!F:F,"불량") -> 0 | AY8: =SUMIFS('센터 자재 사용내역(09월)'!G:G,'센터 자재 사용내역(09월)'!E:E,'사급자재 사용내역'!C8,'센터 자재 사용내역(09월)'!F:F,"불량") -> 0 | AZ8: =SUMIFS('센터 자재 사용내역(10월)'!G:G,'센터 자재 사용내역(10월)'!E:E,'사급자재 사용내역'!C8,'센터 자재 사용내역(10월)'!F:F,"불량") -> 0 | BA8: =SUMIFS('센터 자재 사용내역(11월)'!G:G,'센터 자재 사용내역(11월)'!E:E,'사급자재 사용내역'!C8,'센터 자재 사용내역(11월)'!F:F,"불량") -> 0 | BB8: =SUMIFS('센터 자재 사용내역(12월)'!G:G,'센터 자재 사용내역(12월)'!E:E,'사급자재 사용내역'!C8,'센터 자재 사용내역(12월)'!F:F,"불량") -> 0 | BC8: =SUM(AQ8:BB8) -> 1
C9: Mini ONU, VTN200(1x1, DFBT) | D9: EA | E9: 2 | F9: 0 | I9: =(F9+BC9)-(G9+H9) -> 0 | J9: =Y9 -> 0 | K9: =AN9 -> 0 | L9: =E9-J9+K9 -> 2 | M9: =SUMIFS('센터 자재 사용내역(01월)'!G:G,'센터 자재 사용내역(01월)'!E:E,'사급자재 사용내역'!C9,'센터 자재 사용내역(01월)'!F:F,"신규")+SUMIFS('센터 자재 사용내역(01월)'!G:G,'센터 자재 사용내역(01월)'!E:E,'사급자재 사용내역'!C9,'센터 자재 사용내역(01월)'!F:F,"교체") -> 0 | N9: =SUMIFS('센터 자재 사용내역(02월)'!G:G,'센터 자재 사용내역(02월)'!E:E,'사급자재 사용내역'!C9,'센터 자재 사용내역(02월)'!F:F,"신규")+SUMIFS('센터 자재 사용내역(02월)'!G:G,'센터 자재 사용내역(02월)'!E:E,'사급자재 사용내역'!C9,'센터 자재 사용내역(02월)'!F:F,"교체") -> 0 | O9: =SUMIFS('센터 자재 사용내역(03월)'!G:G,'센터 자재 사용내역(03월)'!E:E,'사급자재 사용내역'!C9,'센터 자재 사용내역(03월)'!F:F,"신규")+SUMIFS('센터 자재 사용내역(03월)'!G:G,'센터 자재 사용내역(03월)'!E:E,'사급자재 사용내역'!C9,'센터 자재 사용내역(03월)'!F:F,"교체") -> 0 | P9: =SUMIFS('센터 자재 사용내역(04월)'!G:G,'센터 자재 사용내역(04월)'!E:E,'사급자재 사용내역'!C9,'센터 자재 사용내역(04월)'!F:F,"신규")+SUMIFS('센터 자재 사용내역(04월)'!G:G,'센터 자재 사용내역(04월)'!E:E,'사급자재 사용내역'!C9,'센터 자재 사용내역(04월)'!F:F,"교체") -> 0 | Q9: =SUMIFS('센터 자재 사용내역(05월)'!G:G,'센터 자재 사용내역(05월)'!E:E,'사급자재 사용내역'!C9,'센터 자재 사용내역(05월)'!F:F,"신규")+SUMIFS('센터 자재 사용내역(05월)'!G:G,'센터 자재 사용내역(05월)'!E:E,'사급자재 사용내역'!C9,'센터 자재 사용내역(05월)'!F:F,"교체") -> 0 | R9: =SUMIFS('센터 자재 사용내역(06월)'!G:G,'센터 자재 사용내역(06월)'!E:E,'사급자재 사용내역'!C9,'센터 자재 사용내역(06월)'!F:F,"신규")+SUMIFS('센터 자재 사용내역(06월)'!G:G,'센터 자재 사용내역(06월)'!E:E,'사급자재 사용내역'!C9,'센터 자재 사용내역(06월)'!F:F,"교체") -> 0 | S9: =SUMIFS('센터 자재 사용내역(07월)'!G:G,'센터 자재 사용내역(07월)'!E:E,'사급자재 사용내역'!C9,'센터 자재 사용내역(07월)'!F:F,"신규")+SUMIFS('센터 자재 사용내역(07월)'!G:G,'센터 자재 사용내역(07월)'!E:E,'사급자재 사용내역'!C9,'센터 자재 사용내역(07월)'!F:F,"교체") -> 0 | T9: =SUMIFS('센터 자재 사용내역(08월)'!G:G,'센터 자재 사용내역(08월)'!E:E,'사급자재 사용내역'!C9,'센터 자재 사용내역(08월)'!F:F,"신규")+SUMIFS('센터 자재 사용내역(08월)'!G:G,'센터 자재 사용내역(08월)'!E:E,'사급자재 사용내역'!C9,'센터 자재 사용내역(08월)'!F:F,"교체") -> 0 | U9: =SUMIFS('센터 자재 사용내역(09월)'!G:G,'센터 자재 사용내역(09월)'!E:E,'사급자재 사용내역'!C9,'센터 자재 사용내역(09월)'!F:F,"신규")+SUMIFS('센터 자재 사용내역(09월)'!G:G,'센터 자재 사용내역(09월)'!E:E,'사급자재 사용내역'!C9,'센터 자재 사용내역(09월)'!F:F,"교체") -> 0 | V9: =SUMIFS('센터 자재 사용내역(10월)'!G:G,'센터 자재 사용내역(10월)'!E:E,'사급자재 사용내역'!C9,'센터 자재 사용내역(10월)'!F:F,"신규")+SUMIFS('센터 자재 사용내역(10월)'!G:G,'센터 자재 사용내역(10월)'!E:E,'사급자재 사용내역'!C9,'센터 자재 사용내역(10월)'!F:F,"교체") -> 0 | W9: =SUMIFS('센터 자재 사용내역(11월)'!G:G,'센터 자재 사용내역(11월)'!E:E,'사급자재 사용내역'!C9,'센터 자재 사용내역(11월)'!F:F,"신규")+SUMIFS('센터 자재 사용내역(11월)'!G:G,'센터 자재 사용내역(11월)'!E:E,'사급자재 사용내역'!C9,'센터 자재 사용내역(11월)'!F:F,"교체") -> 0 | X9: =SUMIFS('센터 자재 사용내역(12월)'!G:G,'센터 자재 사용내역(12월)'!E:E,'사급자재 사용내역'!C9,'센터 자재 사용내역(12월)'!F:F,"신규")+SUMIFS('센터 자재 사용내역(12월)'!G:G,'센터 자재 사용내역(12월)'!E:E,'사급자재 사용내역'!C9,'센터 자재 사용내역(12월)'!F:F,"교체") -> 0 | Y9: =SUM(M9:X9) -> 0 | AN9: =SUM(AB9:AM9) -> 0 | AQ9: =SUMIFS('센터 자재 사용내역(01월)'!G:G,'센터 자재 사용내역(01월)'!E:E,'사급자재 사용내역'!C9,'센터 자재 사용내역(01월)'!F:F,"불량") -> 0 | AR9: =SUMIFS('센터 자재 사용내역(02월)'!G:G,'센터 자재 사용내역(02월)'!E:E,'사급자재 사용내역'!C9,'센터 자재 사용내역(02월)'!F:F,"불량") -> 0 | AS9: =SUMIFS('센터 자재 사용내역(03월)'!G:G,'센터 자재 사용내역(03월)'!E:E,'사급자재 사용내역'!C9,'센터 자재 사용내역(03월)'!F:F,"불량") -> 0 | AT9: =SUMIFS('센터 자재 사용내역(04월)'!G:G,'센터 자재 사용내역(04월)'!E:E,'사급자재 사용내역'!C9,'센터 자재 사용내역(04월)'!F:F,"불량") -> 0 | AU9: =SUMIFS('센터 자재 사용내역(05월)'!G:G,'센터 자재 사용내역(05월)'!E:E,'사급자재 사용내역'!C9,'센터 자재 사용내역(05월)'!F:F,"불량") -> 0 | AV9: =SUMIFS('센터 자재 사용내역(06월)'!G:G,'센터 자재 사용내역(06월)'!E:E,'사급자재 사용내역'!C9,'센터 자재 사용내역(06월)'!F:F,"불량") -> 0 | AW9: =SUMIFS('센터 자재 사용내역(07월)'!G:G,'센터 자재 사용내역(07월)'!E:E,'사급자재 사용내역'!C9,'센터 자재 사용내역(07월)'!F:F,"불량") -> 0 | AX9: =SUMIFS('센터 자재 사용내역(08월)'!G:G,'센터 자재 사용내역(08월)'!E:E,'사급자재 사용내역'!C9,'센터 자재 사용내역(08월)'!F:F,"불량") -> 0 | AY9: =SUMIFS('센터 자재 사용내역(09월)'!G:G,'센터 자재 사용내역(09월)'!E:E,'사급자재 사용내역'!C9,'센터 자재 사용내역(09월)'!F:F,"불량") -> 0 | AZ9: =SUMIFS('센터 자재 사용내역(10월)'!G:G,'센터 자재 사용내역(10월)'!E:E,'사급자재 사용내역'!C9,'센터 자재 사용내역(10월)'!F:F,"불량") -> 0 | BA9: =SUMIFS('센터 자재 사용내역(11월)'!G:G,'센터 자재 사용내역(11월)'!E:E,'사급자재 사용내역'!C9,'센터 자재 사용내역(11월)'!F:F,"불량") -> 0 | BB9: =SUMIFS('센터 자재 사용내역(12월)'!G:G,'센터 자재 사용내역(12월)'!E:E,'사급자재 사용내역'!C9,'센터 자재 사용내역(12월)'!F:F,"불량") -> 0 | BC9: =SUM(AQ9:BB9) -> 0
C10: 텔라움 - TON10A-C(2*2) | D10: EA | E10: 3 | F10: 0 | I10: =(F10+BC10)-(G10+H10) -> 0 | J10: =Y10 -> 1 | K10: =AN10 -> 0 | L10: =E10-J10+K10 -> 2 | M10: =SUMIFS('센터 자재 사용내역(01월)'!G:G,'센터 자재 사용내역(01월)'!E:E,'사급자재 사용내역'!C10,'센터 자재 사용내역(01월)'!F:F,"신규")+SUMIFS('센터 자재 사용내역(01월)'!G:G,'센터 자재 사용내역(01월)'!E:E,'사급자재 사용내역'!C10,'센터 자재 사용내역(01월)'!F:F,"교체") -> 0 | N10: =SUMIFS('센터 자재 사용내역(02월)'!G:G,'센터 자재 사용내역(02월)'!E:E,'사급자재 사용내역'!C10,'센터 자재 사용내역(02월)'!F:F,"신규")+SUMIFS('센터 자재 사용내역(02월)'!G:G,'센터 자재 사용내역(02월)'!E:E,'사급자재 사용내역'!C10,'센터 자재 사용내역(02월)'!F:F,"교체") -> 0 | O10: =SUMIFS('센터 자재 사용내역(03월)'!G:G,'센터 자재 사용내역(03월)'!E:E,'사급자재 사용내역'!C10,'센터 자재 사용내역(03월)'!F:F,"신규")+SUMIFS('센터 자재 사용내역(03월)'!G:G,'센터 자재 사용내역(03월)'!E:E,'사급자재 사용내역'!C10,'센터 자재 사용내역(03월)'!F:F,"교체") -> 0 | P10: =SUMIFS('센터 자재 사용내역(04월)'!G:G,'센터 자재 사용내역(04월)'!E:E,'사급자재 사용내역'!C10,'센터 자재 사용내역(04월)'!F:F,"신규")+SUMIFS('센터 자재 사용내역(04월)'!G:G,'센터 자재 사용내역(04월)'!E:E,'사급자재 사용내역'!C10,'센터 자재 사용내역(04월)'!F:F,"교체") -> 0 | Q10: =SUMIFS('센터 자재 사용내역(05월)'!G:G,'센터 자재 사용내역(05월)'!E:E,'사급자재 사용내역'!C10,'센터 자재 사용내역(05월)'!F:F,"신규")+SUMIFS('센터 자재 사용내역(05월)'!G:G,'센터 자재 사용내역(05월)'!E:E,'사급자재 사용내역'!C10,'센터 자재 사용내역(05월)'!F:F,"교체") -> 1 | R10: =SUMIFS('센터 자재 사용내역(06월)'!G:G,'센터 자재 사용내역(06월)'!E:E,'사급자재 사용내역'!C10,'센터 자재 사용내역(06월)'!F:F,"신규")+SUMIFS('센터 자재 사용내역(06월)'!G:G,'센터 자재 사용내역(06월)'!E:E,'사급자재 사용내역'!C10,'센터 자재 사용내역(06월)'!F:F,"교체") -> 0 | S10: =SUMIFS('센터 자재 사용내역(07월)'!G:G,'센터 자재 사용내역(07월)'!E:E,'사급자재 사용내역'!C10,'센터 자재 사용내역(07월)'!F:F,"신규")+SUMIFS('센터 자재 사용내역(07월)'!G:G,'센터 자재 사용내역(07월)'!E:E,'사급자재 사용내역'!C10,'센터 자재 사용내역(07월)'!F:F,"교체") -> 0 | T10: =SUMIFS('센터 자재 사용내역(08월)'!G:G,'센터 자재 사용내역(08월)'!E:E,'사급자재 사용내역'!C10,'센터 자재 사용내역(08월)'!F:F,"신규")+SUMIFS('센터 자재 사용내역(08월)'!G:G,'센터 자재 사용내역(08월)'!E:E,'사급자재 사용내역'!C10,'센터 자재 사용내역(08월)'!F:F,"교체") -> 0 | U10: =SUMIFS('센터 자재 사용내역(09월)'!G:G,'센터 자재 사용내역(09월)'!E:E,'사급자재 사용내역'!C10,'센터 자재 사용내역(09월)'!F:F,"신규")+SUMIFS('센터 자재 사용내역(09월)'!G:G,'센터 자재 사용내역(09월)'!E:E,'사급자재 사용내역'!C10,'센터 자재 사용내역(09월)'!F:F,"교체") -> 0 | V10: =SUMIFS('센터 자재 사용내역(10월)'!G:G,'센터 자재 사용내역(10월)'!E:E,'사급자재 사용내역'!C10,'센터 자재 사용내역(10월)'!F:F,"신규")+SUMIFS('센터 자재 사용내역(10월)'!G:G,'센터 자재 사용내역(10월)'!E:E,'사급자재 사용내역'!C10,'센터 자재 사용내역(10월)'!F:F,"교체") -> 0 | W10: =SUMIFS('센터 자재 사용내역(11월)'!G:G,'센터 자재 사용내역(11월)'!E:E,'사급자재 사용내역'!C10,'센터 자재 사용내역(11월)'!F:F,"신규")+SUMIFS('센터 자재 사용내역(11월)'!G:G,'센터 자재 사용내역(11월)'!E:E,'사급자재 사용내역'!C10,'센터 자재 사용내역(11월)'!F:F,"교체") -> 0 | X10: =SUMIFS('센터 자재 사용내역(12월)'!G:G,'센터 자재 사용내역(12월)'!E:E,'사급자재 사용내역'!C10,'센터 자재 사용내역(12월)'!F:F,"신규")+SUMIFS('센터 자재 사용내역(12월)'!G:G,'센터 자재 사용내역(12월)'!E:E,'사급자재 사용내역'!C10,'센터 자재 사용내역(12월)'!F:F,"교체") -> 0 | Y10: =SUM(M10:X10) -> 1 | AN10: =SUM(AB10:AM10) -> 0 | AQ10: =SUMIFS('센터 자재 사용내역(01월)'!G:G,'센터 자재 사용내역(01월)'!E:E,'사급자재 사용내역'!C10,'센터 자재 사용내역(01월)'!F:F,"불량") -> 0 | AR10: =SUMIFS('센터 자재 사용내역(02월)'!G:G,'센터 자재 사용내역(02월)'!E:E,'사급자재 사용내역'!C10,'센터 자재 사용내역(02월)'!F:F,"불량") -> 0 | AS10: =SUMIFS('센터 자재 사용내역(03월)'!G:G,'센터 자재 사용내역(03월)'!E:E,'사급자재 사용내역'!C10,'센터 자재 사용내역(03월)'!F:F,"불량") -> 0 | AT10: =SUMIFS('센터 자재 사용내역(04월)'!G:G,'센터 자재 사용내역(04월)'!E:E,'사급자재 사용내역'!C10,'센터 자재 사용내역(04월)'!F:F,"불량") -> 0 | AU10: =SUMIFS('센터 자재 사용내역(05월)'!G:G,'센터 자재 사용내역(05월)'!E:E,'사급자재 사용내역'!C10,'센터 자재 사용내역(05월)'!F:F,"불량") -> 0 | AV10: =SUMIFS('센터 자재 사용내역(06월)'!G:G,'센터 자재 사용내역(06월)'!E:E,'사급자재 사용내역'!C10,'센터 자재 사용내역(06월)'!F:F,"불량") -> 0 | AW10: =SUMIFS('센터 자재 사용내역(07월)'!G:G,'센터 자재 사용내역(07월)'!E:E,'사급자재 사용내역'!C10,'센터 자재 사용내역(07월)'!F:F,"불량") -> 0 | AX10: =SUMIFS('센터 자재 사용내역(08월)'!G:G,'센터 자재 사용내역(08월)'!E:E,'사급자재 사용내역'!C10,'센터 자재 사용내역(08월)'!F:F,"불량") -> 0 | AY10: =SUMIFS('센터 자재 사용내역(09월)'!G:G,'센터 자재 사용내역(09월)'!E:E,'사급자재 사용내역'!C10,'센터 자재 사용내역(09월)'!F:F,"불량") -> 0 | AZ10: =SUMIFS('센터 자재 사용내역(10월)'!G:G,'센터 자재 사용내역(10월)'!E:E,'사급자재 사용내역'!C10,'센터 자재 사용내역(10월)'!F:F,"불량") -> 0 | BA10: =SUMIFS('센터 자재 사용내역(11월)'!G:G,'센터 자재 사용내역(11월)'!E:E,'사급자재 사용내역'!C10,'센터 자재 사용내역(11월)'!F:F,"불량") -> 0 | BB10: =SUMIFS('센터 자재 사용내역(12월)'!G:G,'센터 자재 사용내역(12월)'!E:E,'사급자재 사용내역'!C10,'센터 자재 사용내역(12월)'!F:F,"불량") -> 0 | BC10: =SUM(AQ10:BB10) -> 0
C11: 텔라움 V-ONU(RF_Overlay) TOV10P-H(49dBmv) | D11: EA | E11: 3 | F11: 0 | I11: =(F11+BC11)-(G11+H11) -> 0 | J11: =Y11 -> 0 | K11: =AN11 -> 0 | L11: =E11-J11+K11 -> 3 | M11: =SUMIFS('센터 자재 사용내역(01월)'!G:G,'센터 자재 사용내역(01월)'!E:E,'사급자재 사용내역'!C11,'센터 자재 사용내역(01월)'!F:F,"신규")+SUMIFS('센터 자재 사용내역(01월)'!G:G,'센터 자재 사용내역(01월)'!E:E,'사급자재 사용내역'!C11,'센터 자재 사용내역(01월)'!F:F,"교체") -> 0 | N11: =SUMIFS('센터 자재 사용내역(02월)'!G:G,'센터 자재 사용내역(02월)'!E:E,'사급자재 사용내역'!C11,'센터 자재 사용내역(02월)'!F:F,"신규")+SUMIFS('센터 자재 사용내역(02월)'!G:G,'센터 자재 사용내역(02월)'!E:E,'사급자재 사용내역'!C11,'센터 자재 사용내역(02월)'!F:F,"교체") -> 0 | O11: =SUMIFS('센터 자재 사용내역(03월)'!G:G,'센터 자재 사용내역(03월)'!E:E,'사급자재 사용내역'!C11,'센터 자재 사용내역(03월)'!F:F,"신규")+SUMIFS('센터 자재 사용내역(03월)'!G:G,'센터 자재 사용내역(03월)'!E:E,'사급자재 사용내역'!C11,'센터 자재 사용내역(03월)'!F:F,"교체") -> 0 | P11: =SUMIFS('센터 자재 사용내역(04월)'!G:G,'센터 자재 사용내역(04월)'!E:E,'사급자재 사용내역'!C11,'센터 자재 사용내역(04월)'!F:F,"신규")+SUMIFS('센터 자재 사용내역(04월)'!G:G,'센터 자재 사용내역(04월)'!E:E,'사급자재 사용내역'!C11,'센터 자재 사용내역(04월)'!F:F,"교체") -> 0 | Q11: =SUMIFS('센터 자재 사용내역(05월)'!G:G,'센터 자재 사용내역(05월)'!E:E,'사급자재 사용내역'!C11,'센터 자재 사용내역(05월)'!F:F,"신규")+SUMIFS('센터 자재 사용내역(05월)'!G:G,'센터 자재 사용내역(05월)'!E:E,'사급자재 사용내역'!C11,'센터 자재 사용내역(05월)'!F:F,"교체") -> 0 | R11: =SUMIFS('센터 자재 사용내역(06월)'!G:G,'센터 자재 사용내역(06월)'!E:E,'사급자재 사용내역'!C11,'센터 자재 사용내역(06월)'!F:F,"신규")+SUMIFS('센터 자재 사용내역(06월)'!G:G,'센터 자재 사용내역(06월)'!E:E,'사급자재 사용내역'!C11,'센터 자재 사용내역(06월)'!F:F,"교체") -> 0 | S11: =SUMIFS('센터 자재 사용내역(07월)'!G:G,'센터 자재 사용내역(07월)'!E:E,'사급자재 사용내역'!C11,'센터 자재 사용내역(07월)'!F:F,"신규")+SUMIFS('센터 자재 사용내역(07월)'!G:G,'센터 자재 사용내역(07월)'!E:E,'사급자재 사용내역'!C11,'센터 자재 사용내역(07월)'!F:F,"교체") -> 0 | T11: =SUMIFS('센터 자재 사용내역(08월)'!G:G,'센터 자재 사용내역(08월)'!E:E,'사급자재 사용내역'!C11,'센터 자재 사용내역(08월)'!F:F,"신규")+SUMIFS('센터 자재 사용내역(08월)'!G:G,'센터 자재 사용내역(08월)'!E:E,'사급자재 사용내역'!C11,'센터 자재 사용내역(08월)'!F:F,"교체") -> 0 | U11: =SUMIFS('센터 자재 사용내역(09월)'!G:G,'센터 자재 사용내역(09월)'!E:E,'사급자재 사용내역'!C11,'센터 자재 사용내역(09월)'!F:F,"신규")+SUMIFS('센터 자재 사용내역(09월)'!G:G,'센터 자재 사용내역(09월)'!E:E,'사급자재 사용내역'!C11,'센터 자재 사용내역(09월)'!F:F,"교체") -> 0 | V11: =SUMIFS('센터 자재 사용내역(10월)'!G:G,'센터 자재 사용내역(10월)'!E:E,'사급자재 사용내역'!C11,'센터 자재 사용내역(10월)'!F:F,"신규")+SUMIFS('센터 자재 사용내역(10월)'!G:G,'센터 자재 사용내역(10월)'!E:E,'사급자재 사용내역'!C11,'센터 자재 사용내역(10월)'!F:F,"교체") -> 0 | W11: =SUMIFS('센터 자재 사용내역(11월)'!G:G,'센터 자재 사용내역(11월)'!E:E,'사급자재 사용내역'!C11,'센터 자재 사용내역(11월)'!F:F,"신규")+SUMIFS('센터 자재 사용내역(11월)'!G:G,'센터 자재 사용내역(11월)'!E:E,'사급자재 사용내역'!C11,'센터 자재 사용내역(11월)'!F:F,"교체") -> 0 | X11: =SUMIFS('센터 자재 사용내역(12월)'!G:G,'센터 자재 사용내역(12월)'!E:E,'사급자재 사용내역'!C11,'센터 자재 사용내역(12월)'!F:F,"신규")+SUMIFS('센터 자재 사용내역(12월)'!G:G,'센터 자재 사용내역(12월)'!E:E,'사급자재 사용내역'!C11,'센터 자재 사용내역(12월)'!F:F,"교체") -> 0 | Y11: =SUM(M11:X11) -> 0 | AN11: =SUM(AB11:AM11) -> 0 | AQ11: =SUMIFS('센터 자재 사용내역(01월)'!G:G,'센터 자재 사용내역(01월)'!E:E,'사급자재 사용내역'!C11,'센터 자재 사용내역(01월)'!F:F,"불량") -> 0 | AR11: =SUMIFS('센터 자재 사용내역(02월)'!G:G,'센터 자재 사용내역(02월)'!E:E,'사급자재 사용내역'!C11,'센터 자재 사용내역(02월)'!F:F,"불량") -> 0 | AS11: =SUMIFS('센터 자재 사용내역(03월)'!G:G,'센터 자재 사용내역(03월)'!E:E,'사급자재 사용내역'!C11,'센터 자재 사용내역(03월)'!F:F,"불량") -> 0 | AT11: =SUMIFS('센터 자재 사용내역(04월)'!G:G,'센터 자재 사용내역(04월)'!E:E,'사급자재 사용내역'!C11,'센터 자재 사용내역(04월)'!F:F,"불량") -> 0 | AU11: =SUMIFS('센터 자재 사용내역(05월)'!G:G,'센터 자재 사용내역(05월)'!E:E,'사급자재 사용내역'!C11,'센터 자재 사용내역(05월)'!F:F,"불량") -> 0 | AV11: =SUMIFS('센터 자재 사용내역(06월)'!G:G,'센터 자재 사용내역(06월)'!E:E,'사급자재 사용내역'!C11,'센터 자재 사용내역(06월)'!F:F,"불량") -> 0 | AW11: =SUMIFS('센터 자재 사용내역(07월)'!G:G,'센터 자재 사용내역(07월)'!E:E,'사급자재 사용내역'!C11,'센터 자재 사용내역(07월)'!F:F,"불량") -> 0 | AX11: =SUMIFS('센터 자재 사용내역(08월)'!G:G,'센터 자재 사용내역(08월)'!E:E,'사급자재 사용내역'!C11,'센터 자재 사용내역(08월)'!F:F,"불량") -> 0 | AY11: =SUMIFS('센터 자재 사용내역(09월)'!G:G,'센터 자재 사용내역(09월)'!E:E,'사급자재 사용내역'!C11,'센터 자재 사용내역(09월)'!F:F,"불량") -> 0 | AZ11: =SUMIFS('센터 자재 사용내역(10월)'!G:G,'센터 자재 사용내역(10월)'!E:E,'사급자재 사용내역'!C11,'센터 자재 사용내역(10월)'!F:F,"불량") -> 0 | BA11: =SUMIFS('센터 자재 사용내역(11월)'!G:G,'센터 자재 사용내역(11월)'!E:E,'사급자재 사용내역'!C11,'센터 자재 사용내역(11월)'!F:F,"불량") -> 0 | BB11: =SUMIFS('센터 자재 사용내역(12월)'!G:G,'센터 자재 사용내역(12월)'!E:E,'사급자재 사용내역'!C11,'센터 자재 사용내역(12월)'!F:F,"불량") -> 0 | BC11: =SUM(AQ11:BB11) -> 0
C12: 모토로라 - SG4-100SK/SXX-CNN-S | D12: EA | E12: 0 | F12: 0 | I12: =(F12+BC12)-(G12+H12) -> 0 | J12: =Y12 -> 0 | K12: =AN12 -> 0 | L12: =E12-J12+K12 -> 0 | M12: =SUMIFS('센터 자재 사용내역(01월)'!G:G,'센터 자재 사용내역(01월)'!E:E,'사급자재 사용내역'!C12,'센터 자재 사용내역(01월)'!F:F,"신규")+SUMIFS('센터 자재 사용내역(01월)'!G:G,'센터 자재 사용내역(01월)'!E:E,'사급자재 사용내역'!C12,'센터 자재 사용내역(01월)'!F:F,"교체") -> 0 | N12: =SUMIFS('센터 자재 사용내역(02월)'!G:G,'센터 자재 사용내역(02월)'!E:E,'사급자재 사용내역'!C12,'센터 자재 사용내역(02월)'!F:F,"신규")+SUMIFS('센터 자재 사용내역(02월)'!G:G,'센터 자재 사용내역(02월)'!E:E,'사급자재 사용내역'!C12,'센터 자재 사용내역(02월)'!F:F,"교체") -> 0 | O12: =SUMIFS('센터 자재 사용내역(03월)'!G:G,'센터 자재 사용내역(03월)'!E:E,'사급자재 사용내역'!C12,'센터 자재 사용내역(03월)'!F:F,"신규")+SUMIFS('센터 자재 사용내역(03월)'!G:G,'센터 자재 사용내역(03월)'!E:E,'사급자재 사용내역'!C12,'센터 자재 사용내역(03월)'!F:F,"교체") -> 0 | P12: =SUMIFS('센터 자재 사용내역(04월)'!G:G,'센터 자재 사용내역(04월)'!E:E,'사급자재 사용내역'!C12,'센터 자재 사용내역(04월)'!F:F,"신규")+SUMIFS('센터 자재 사용내역(04월)'!G:G,'센터 자재 사용내역(04월)'!E:E,'사급자재 사용내역'!C12,'센터 자재 사용내역(04월)'!F:F,"교체") -> 0 | Q12: =SUMIFS('센터 자재 사용내역(05월)'!G:G,'센터 자재 사용내역(05월)'!E:E,'사급자재 사용내역'!C12,'센터 자재 사용내역(05월)'!F:F,"신규")+SUMIFS('센터 자재 사용내역(05월)'!G:G,'센터 자재 사용내역(05월)'!E:E,'사급자재 사용내역'!C12,'센터 자재 사용내역(05월)'!F:F,"교체") -> 0 | R12: =SUMIFS('센터 자재 사용내역(06월)'!G:G,'센터 자재 사용내역(06월)'!E:E,'사급자재 사용내역'!C12,'센터 자재 사용내역(06월)'!F:F,"신규")+SUMIFS('센터 자재 사용내역(06월)'!G:G,'센터 자재 사용내역(06월)'!E:E,'사급자재 사용내역'!C12,'센터 자재 사용내역(06월)'!F:F,"교체") -> 0 | S12: =SUMIFS('센터 자재 사용내역(07월)'!G:G,'센터 자재 사용내역(07월)'!E:E,'사급자재 사용내역'!C12,'센터 자재 사용내역(07월)'!F:F,"신규")+SUMIFS('센터 자재 사용내역(07월)'!G:G,'센터 자재 사용내역(07월)'!E:E,'사급자재 사용내역'!C12,'센터 자재 사용내역(07월)'!F:F,"교체") -> 0 | T12: =SUMIFS('센터 자재 사용내역(08월)'!G:G,'센터 자재 사용내역(08월)'!E:E,'사급자재 사용내역'!C12,'센터 자재 사용내역(08월)'!F:F,"신규")+SUMIFS('센터 자재 사용내역(08월)'!G:G,'센터 자재 사용내역(08월)'!E:E,'사급자재 사용내역'!C12,'센터 자재 사용내역(08월)'!F:F,"교체") -> 0 | U12: =SUMIFS('센터 자재 사용내역(09월)'!G:G,'센터 자재 사용내역(09월)'!E:E,'사급자재 사용내역'!C12,'센터 자재 사용내역(09월)'!F:F,"신규")+SUMIFS('센터 자재 사용내역(09월)'!G:G,'센터 자재 사용내역(09월)'!E:E,'사급자재 사용내역'!C12,'센터 자재 사용내역(09월)'!F:F,"교체") -> 0 | V12: =SUMIFS('센터 자재 사용내역(10월)'!G:G,'센터 자재 사용내역(10월)'!E:E,'사급자재 사용내역'!C12,'센터 자재 사용내역(10월)'!F:F,"신규")+SUMIFS('센터 자재 사용내역(10월)'!G:G,'센터 자재 사용내역(10월)'!E:E,'사급자재 사용내역'!C12,'센터 자재 사용내역(10월)'!F:F,"교체") -> 0 | W12: =SUMIFS('센터 자재 사용내역(11월)'!G:G,'센터 자재 사용내역(11월)'!E:E,'사급자재 사용내역'!C12,'센터 자재 사용내역(11월)'!F:F,"신규")+SUMIFS('센터 자재 사용내역(11월)'!G:G,'센터 자재 사용내역(11월)'!E:E,'사급자재 사용내역'!C12,'센터 자재 사용내역(11월)'!F:F,"교체") -> 0 | X12: =SUMIFS('센터 자재 사용내역(12월)'!G:G,'센터 자재 사용내역(12월)'!E:E,'사급자재 사용내역'!C12,'센터 자재 사용내역(12월)'!F:F,"신규")+SUMIFS('센터 자재 사용내역(12월)'!G:G,'센터 자재 사용내역(12월)'!E:E,'사급자재 사용내역'!C12,'센터 자재 사용내역(12월)'!F:F,"교체") -> 0 | Y12: =SUM(M12:X12) -> 0 | AN12: =SUM(AB12:AM12) -> 0 | AQ12: =SUMIFS('센터 자재 사용내역(01월)'!G:G,'센터 자재 사용내역(01월)'!E:E,'사급자재 사용내역'!C12,'센터 자재 사용내역(01월)'!F:F,"불량") -> 0 | AR12: =SUMIFS('센터 자재 사용내역(02월)'!G:G,'센터 자재 사용내역(02월)'!E:E,'사급자재 사용내역'!C12,'센터 자재 사용내역(02월)'!F:F,"불량") -> 0 | AS12: =SUMIFS('센터 자재 사용내역(03월)'!G:G,'센터 자재 사용내역(03월)'!E:E,'사급자재 사용내역'!C12,'센터 자재 사용내역(03월)'!F:F,"불량") -> 0 | AT12: =SUMIFS('센터 자재 사용내역(04월)'!G:G,'센터 자재 사용내역(04월)'!E:E,'사급자재 사용내역'!C12,'센터 자재 사용내역(04월)'!F:F,"불량") -> 0 | AU12: =SUMIFS('센터 자재 사용내역(05월)'!G:G,'센터 자재 사용내역(05월)'!E:E,'사급자재 사용내역'!C12,'센터 자재 사용내역(05월)'!F:F,"불량") -> 0 | AV12: =SUMIFS('센터 자재 사용내역(06월)'!G:G,'센터 자재 사용내역(06월)'!E:E,'사급자재 사용내역'!C12,'센터 자재 사용내역(06월)'!F:F,"불량") -> 0 | AW12: =SUMIFS('센터 자재 사용내역(07월)'!G:G,'센터 자재 사용내역(07월)'!E:E,'사급자재 사용내역'!C12,'센터 자재 사용내역(07월)'!F:F,"불량") -> 0 | AX12: =SUMIFS('센터 자재 사용내역(08월)'!G:G,'센터 자재 사용내역(08월)'!E:E,'사급자재 사용내역'!C12,'센터 자재 사용내역(08월)'!F:F,"불량") -> 0 | AY12: =SUMIFS('센터 자재 사용내역(09월)'!G:G,'센터 자재 사용내역(09월)'!E:E,'사급자재 사용내역'!C12,'센터 자재 사용내역(09월)'!F:F,"불량") -> 0 | AZ12: =SUMIFS('센터 자재 사용내역(10월)'!G:G,'센터 자재 사용내역(10월)'!E:E,'사급자재 사용내역'!C12,'센터 자재 사용내역(10월)'!F:F,"불량") -> 0 | BA12: =SUMIFS('센터 자재 사용내역(11월)'!G:G,'센터 자재 사용내역(11월)'!E:E,'사급자재 사용내역'!C12,'센터 자재 사용내역(11월)'!F:F,"불량") -> 0 | BB12: =SUMIFS('센터 자재 사용내역(12월)'!G:G,'센터 자재 사용내역(12월)'!E:E,'사급자재 사용내역'!C12,'센터 자재 사용내역(12월)'!F:F,"불량") -> 0 | BC12: =SUM(AQ12:BB12) -> 0
C13: 모토로라 - SG4-87SK/SXX-CNN-S | D13: EA | E13: 2 | F13: 0 | H13: 4 | I13: =(F13+BC13)-(G13+H13) -> 1 | J13: =Y13 -> 1 | K13: =AN13 -> 8 | L13: =E13-J13+K13 -> 9 | M13: =SUMIFS('센터 자재 사용내역(01월)'!G:G,'센터 자재 사용내역(01월)'!E:E,'사급자재 사용내역'!C13,'센터 자재 사용내역(01월)'!F:F,"신규")+SUMIFS('센터 자재 사용내역(01월)'!G:G,'센터 자재 사용내역(01월)'!E:E,'사급자재 사용내역'!C13,'센터 자재 사용내역(01월)'!F:F,"교체") -> 0 | N13: =SUMIFS('센터 자재 사용내역(02월)'!G:G,'센터 자재 사용내역(02월)'!E:E,'사급자재 사용내역'!C13,'센터 자재 사용내역(02월)'!F:F,"신규")+SUMIFS('센터 자재 사용내역(02월)'!G:G,'센터 자재 사용내역(02월)'!E:E,'사급자재 사용내역'!C13,'센터 자재 사용내역(02월)'!F:F,"교체") -> 0 | O13: =SUMIFS('센터 자재 사용내역(03월)'!G:G,'센터 자재 사용내역(03월)'!E:E,'사급자재 사용내역'!C13,'센터 자재 사용내역(03월)'!F:F,"신규")+SUMIFS('센터 자재 사용내역(03월)'!G:G,'센터 자재 사용내역(03월)'!E:E,'사급자재 사용내역'!C13,'센터 자재 사용내역(03월)'!F:F,"교체") -> 0 | P13: =SUMIFS('센터 자재 사용내역(04월)'!G:G,'센터 자재 사용내역(04월)'!E:E,'사급자재 사용내역'!C13,'센터 자재 사용내역(04월)'!F:F,"신규")+SUMIFS('센터 자재 사용내역(04월)'!G:G,'센터 자재 사용내역(04월)'!E:E,'사급자재 사용내역'!C13,'센터 자재 사용내역(04월)'!F:F,"교체") -> 0 | Q13: =SUMIFS('센터 자재 사용내역(05월)'!G:G,'센터 자재 사용내역(05월)'!E:E,'사급자재 사용내역'!C13,'센터 자재 사용내역(05월)'!F:F,"신규")+SUMIFS('센터 자재 사용내역(05월)'!G:G,'센터 자재 사용내역(05월)'!E:E,'사급자재 사용내역'!C13,'센터 자재 사용내역(05월)'!F:F,"교체") -> 0 | R13: =SUMIFS('센터 자재 사용내역(06월)'!G:G,'센터 자재 사용내역(06월)'!E:E,'사급자재 사용내역'!C13,'센터 자재 사용내역(06월)'!F:F,"신규")+SUMIFS('센터 자재 사용내역(06월)'!G:G,'센터 자재 사용내역(06월)'!E:E,'사급자재 사용내역'!C13,'센터 자재 사용내역(06월)'!F:F,"교체") -> 0 | S13: =SUMIFS('센터 자재 사용내역(07월)'!G:G,'센터 자재 사용내역(07월)'!E:E,'사급자재 사용내역'!C13,'센터 자재 사용내역(07월)'!F:F,"신규")+SUMIFS('센터 자재 사용내역(07월)'!G:G,'센터 자재 사용내역(07월)'!E:E,'사급자재 사용내역'!C13,'센터 자재 사용내역(07월)'!F:F,"교체") -> 1 | T13: =SUMIFS('센터 자재 사용내역(08월)'!G:G,'센터 자재 사용내역(08월)'!E:E,'사급자재 사용내역'!C13,'센터 자재 사용내역(08월)'!F:F,"신규")+SUMIFS('센터 자재 사용내역(08월)'!G:G,'센터 자재 사용내역(08월)'!E:E,'사급자재 사용내역'!C13,'센터 자재 사용내역(08월)'!F:F,"교체") -> 0 | U13: =SUMIFS('센터 자재 사용내역(09월)'!G:G,'센터 자재 사용내역(09월)'!E:E,'사급자재 사용내역'!C13,'센터 자재 사용내역(09월)'!F:F,"신규")+SUMIFS('센터 자재 사용내역(09월)'!G:G,'센터 자재 사용내역(09월)'!E:E,'사급자재 사용내역'!C13,'센터 자재 사용내역(09월)'!F:F,"교체") -> 0 | V13: =SUMIFS('센터 자재 사용내역(10월)'!G:G,'센터 자재 사용내역(10월)'!E:E,'사급자재 사용내역'!C13,'센터 자재 사용내역(10월)'!F:F,"신규")+SUMIFS('센터 자재 사용내역(10월)'!G:G,'센터 자재 사용내역(10월)'!E:E,'사급자재 사용내역'!C13,'센터 자재 사용내역(10월)'!F:F,"교체") -> 0 | W13: =SUMIFS('센터 자재 사용내역(11월)'!G:G,'센터 자재 사용내역(11월)'!E:E,'사급자재 사용내역'!C13,'센터 자재 사용내역(11월)'!F:F,"신규")+SUMIFS('센터 자재 사용내역(11월)'!G:G,'센터 자재 사용내역(11월)'!E:E,'사급자재 사용내역'!C13,'센터 자재 사용내역(11월)'!F:F,"교체") -> 0 | X13: =SUMIFS('센터 자재 사용내역(12월)'!G:G,'센터 자재 사용내역(12월)'!E:E,'사급자재 사용내역'!C13,'센터 자재 사용내역(12월)'!F:F,"신규")+SUMIFS('센터 자재 사용내역(12월)'!G:G,'센터 자재 사용내역(12월)'!E:E,'사급자재 사용내역'!C13,'센터 자재 사용내역(12월)'!F:F,"교체") -> 0 | Y13: =SUM(M13:X13) -> 1 | AE13: 3 | AI13: 5 | AN13: =SUM(AB13:AM13) -> 8 | AQ13: =SUMIFS('센터 자재 사용내역(01월)'!G:G,'센터 자재 사용내역(01월)'!E:E,'사급자재 사용내역'!C13,'센터 자재 사용내역(01월)'!F:F,"불량") -> 0 | AR13: =SUMIFS('센터 자재 사용내역(02월)'!G:G,'센터 자재 사용내역(02월)'!E:E,'사급자재 사용내역'!C13,'센터 자재 사용내역(02월)'!F:F,"불량") -> 1 | AS13: =SUMIFS('센터 자재 사용내역(03월)'!G:G,'센터 자재 사용내역(03월)'!E:E,'사급자재 사용내역'!C13,'센터 자재 사용내역(03월)'!F:F,"불량") -> 0 | AT13: =SUMIFS('센터 자재 사용내역(04월)'!G:G,'센터 자재 사용내역(04월)'!E:E,'사급자재 사용내역'!C13,'센터 자재 사용내역(04월)'!F:F,"불량") -> 0 | AU13: =SUMIFS('센터 자재 사용내역(05월)'!G:G,'센터 자재 사용내역(05월)'!E:E,'사급자재 사용내역'!C13,'센터 자재 사용내역(05월)'!F:F,"불량") -> 0 | AV13: =SUMIFS('센터 자재 사용내역(06월)'!G:G,'센터 자재 사용내역(06월)'!E:E,'사급자재 사용내역'!C13,'센터 자재 사용내역(06월)'!F:F,"불량") -> 3 | AW13: =SUMIFS('센터 자재 사용내역(07월)'!G:G,'센터 자재 사용내역(07월)'!E:E,'사급자재 사용내역'!C13,'센터 자재 사용내역(07월)'!F:F,"불량") -> 1 | AX13: =SUMIFS('센터 자재 사용내역(08월)'!G:G,'센터 자재 사용내역(08월)'!E:E,'사급자재 사용내역'!C13,'센터 자재 사용내역(08월)'!F:F,"불량") -> 0 | AY13: =SUMIFS('센터 자재 사용내역(09월)'!G:G,'센터 자재 사용내역(09월)'!E:E,'사급자재 사용내역'!C13,'센터 자재 사용내역(09월)'!F:F,"불량") -> 0 | AZ13: =SUMIFS('센터 자재 사용내역(10월)'!G:G,'센터 자재 사용내역(10월)'!E:E,'사급자재 사용내역'!C13,'센터 자재 사용내역(10월)'!F:F,"불량") -> 0 | BA13: =SUMIFS('센터 자재 사용내역(11월)'!G:G,'센터 자재 사용내역(11월)'!E:E,'사급자재 사용내역'!C13,'센터 자재 사용내역(11월)'!F:F,"불량") -> 0 | BB13: =SUMIFS('센터 자재 사용내역(12월)'!G:G,'센터 자재 사용내역(12월)'!E:E,'사급자재 사용내역'!C13,'센터 자재 사용내역(12월)'!F:F,"불량") -> 0 | BC13: =SUM(AQ13:BB13) -> 5
C14: 모토로라 - SG2440-87KS/DSTX-XAXB | D14: EA | E14: 2 | F14: 0 | H14: 1 | I14: =(F14+BC14)-(G14+H14) -> 2 | J14: =Y14 -> 0 | K14: =AN14 -> 0 | L14: =E14-J14+K14 -> 2 | M14: =SUMIFS('센터 자재 사용내역(01월)'!G:G,'센터 자재 사용내역(01월)'!E:E,'사급자재 사용내역'!C14,'센터 자재 사용내역(01월)'!F:F,"신규")+SUMIFS('센터 자재 사용내역(01월)'!G:G,'센터 자재 사용내역(01월)'!E:E,'사급자재 사용내역'!C14,'센터 자재 사용내역(01월)'!F:F,"교체") -> 0 | N14: =SUMIFS('센터 자재 사용내역(02월)'!G:G,'센터 자재 사용내역(02월)'!E:E,'사급자재 사용내역'!C14,'센터 자재 사용내역(02월)'!F:F,"신규")+SUMIFS('센터 자재 사용내역(02월)'!G:G,'센터 자재 사용내역(02월)'!E:E,'사급자재 사용내역'!C14,'센터 자재 사용내역(02월)'!F:F,"교체") -> 0 | O14: =SUMIFS('센터 자재 사용내역(03월)'!G:G,'센터 자재 사용내역(03월)'!E:E,'사급자재 사용내역'!C14,'센터 자재 사용내역(03월)'!F:F,"신규")+SUMIFS('센터 자재 사용내역(03월)'!G:G,'센터 자재 사용내역(03월)'!E:E,'사급자재 사용내역'!C14,'센터 자재 사용내역(03월)'!F:F,"교체") -> 0 | P14: =SUMIFS('센터 자재 사용내역(04월)'!G:G,'센터 자재 사용내역(04월)'!E:E,'사급자재 사용내역'!C14,'센터 자재 사용내역(04월)'!F:F,"신규")+SUMIFS('센터 자재 사용내역(04월)'!G:G,'센터 자재 사용내역(04월)'!E:E,'사급자재 사용내역'!C14,'센터 자재 사용내역(04월)'!F:F,"교체") -> 0 | Q14: =SUMIFS('센터 자재 사용내역(05월)'!G:G,'센터 자재 사용내역(05월)'!E:E,'사급자재 사용내역'!C14,'센터 자재 사용내역(05월)'!F:F,"신규")+SUMIFS('센터 자재 사용내역(05월)'!G:G,'센터 자재 사용내역(05월)'!E:E,'사급자재 사용내역'!C14,'센터 자재 사용내역(05월)'!F:F,"교체") -> 0 | R14: =SUMIFS('센터 자재 사용내역(06월)'!G:G,'센터 자재 사용내역(06월)'!E:E,'사급자재 사용내역'!C14,'센터 자재 사용내역(06월)'!F:F,"신규")+SUMIFS('센터 자재 사용내역(06월)'!G:G,'센터 자재 사용내역(06월)'!E:E,'사급자재 사용내역'!C14,'센터 자재 사용내역(06월)'!F:F,"교체") -> 0 | S14: =SUMIFS('센터 자재 사용내역(07월)'!G:G,'센터 자재 사용내역(07월)'!E:E,'사급자재 사용내역'!C14,'센터 자재 사용내역(07월)'!F:F,"신규")+SUMIFS('센터 자재 사용내역(07월)'!G:G,'센터 자재 사용내역(07월)'!E:E,'사급자재 사용내역'!C14,'센터 자재 사용내역(07월)'!F:F,"교체") -> 0 | T14: =SUMIFS('센터 자재 사용내역(08월)'!G:G,'센터 자재 사용내역(08월)'!E:E,'사급자재 사용내역'!C14,'센터 자재 사용내역(08월)'!F:F,"신규")+SUMIFS('센터 자재 사용내역(08월)'!G:G,'센터 자재 사용내역(08월)'!E:E,'사급자재 사용내역'!C14,'센터 자재 사용내역(08월)'!F:F,"교체") -> 0 | U14: =SUMIFS('센터 자재 사용내역(09월)'!G:G,'센터 자재 사용내역(09월)'!E:E,'사급자재 사용내역'!C14,'센터 자재 사용내역(09월)'!F:F,"신규")+SUMIFS('센터 자재 사용내역(09월)'!G:G,'센터 자재 사용내역(09월)'!E:E,'사급자재 사용내역'!C14,'센터 자재 사용내역(09월)'!F:F,"교체") -> 0 | V14: =SUMIFS('센터 자재 사용내역(10월)'!G:G,'센터 자재 사용내역(10월)'!E:E,'사급자재 사용내역'!C14,'센터 자재 사용내역(10월)'!F:F,"신규")+SUMIFS('센터 자재 사용내역(10월)'!G:G,'센터 자재 사용내역(10월)'!E:E,'사급자재 사용내역'!C14,'센터 자재 사용내역(10월)'!F:F,"교체") -> 0 | W14: =SUMIFS('센터 자재 사용내역(11월)'!G:G,'센터 자재 사용내역(11월)'!E:E,'사급자재 사용내역'!C14,'센터 자재 사용내역(11월)'!F:F,"신규")+SUMIFS('센터 자재 사용내역(11월)'!G:G,'센터 자재 사용내역(11월)'!E:E,'사급자재 사용내역'!C14,'센터 자재 사용내역(11월)'!F:F,"교체") -> 0 | X14: =SUMIFS('센터 자재 사용내역(12월)'!G:G,'센터 자재 사용내역(12월)'!E:E,'사급자재 사용내역'!C14,'센터 자재 사용내역(12월)'!F:F,"신규")+SUMIFS('센터 자재 사용내역(12월)'!G:G,'센터 자재 사용내역(12월)'!E:E,'사급자재 사용내역'!C14,'센터 자재 사용내역(12월)'!F:F,"교체") -> 0 | Y14: =SUM(M14:X14) -> 0 | AN14: =SUM(AB14:AM14) -> 0 | AQ14: =SUMIFS('센터 자재 사용내역(01월)'!G:G,'센터 자재 사용내역(01월)'!E:E,'사급자재 사용내역'!C14,'센터 자재 사용내역(01월)'!F:F,"불량") -> 1 | AR14: =SUMIFS('센터 자재 사용내역(02월)'!G:G,'센터 자재 사용내역(02월)'!E:E,'사급자재 사용내역'!C14,'센터 자재 사용내역(02월)'!F:F,"불량") -> 0 | AS14: =SUMIFS('센터 자재 사용내역(03월)'!G:G,'센터 자재 사용내역(03월)'!E:E,'사급자재 사용내역'!C14,'센터 자재 사용내역(03월)'!F:F,"불량") -> 0 | AT14: =SUMIFS('센터 자재 사용내역(04월)'!G:G,'센터 자재 사용내역(04월)'!E:E,'사급자재 사용내역'!C14,'센터 자재 사용내역(04월)'!F:F,"불량") -> 0 | AU14: =SUMIFS('센터 자재 사용내역(05월)'!G:G,'센터 자재 사용내역(05월)'!E:E,'사급자재 사용내역'!C14,'센터 자재 사용내역(05월)'!F:F,"불량") -> 0 | AV14: =SUMIFS('센터 자재 사용내역(06월)'!G:G,'센터 자재 사용내역(06월)'!E:E,'사급자재 사용내역'!C14,'센터 자재 사용내역(06월)'!F:F,"불량") -> 0 | AW14: =SUMIFS('센터 자재 사용내역(07월)'!G:G,'센터 자재 사용내역(07월)'!E:E,'사급자재 사용내역'!C14,'센터 자재 사용내역(07월)'!F:F,"불량") -> 1 | AX14: =SUMIFS('센터 자재 사용내역(08월)'!G:G,'센터 자재 사용내역(08월)'!E:E,'사급자재 사용내역'!C14,'센터 자재 사용내역(08월)'!F:F,"불량") -> 1 | AY14: =SUMIFS('센터 자재 사용내역(09월)'!G:G,'센터 자재 사용내역(09월)'!E:E,'사급자재 사용내역'!C14,'센터 자재 사용내역(09월)'!F:F,"불량") -> 0 | AZ14: =SUMIFS('센터 자재 사용내역(10월)'!G:G,'센터 자재 사용내역(10월)'!E:E,'사급자재 사용내역'!C14,'센터 자재 사용내역(10월)'!F:F,"불량") -> 0 | BA14: =SUMIFS('센터 자재 사용내역(11월)'!G:G,'센터 자재 사용내역(11월)'!E:E,'사급자재 사용내역'!C14,'센터 자재 사용내역(11월)'!F:F,"불량") -> 0 | BB14: =SUMIFS('센터 자재 사용내역(12월)'!G:G,'센터 자재 사용내역(12월)'!E:E,'사급자재 사용내역'!C14,'센터 자재 사용내역(12월)'!F:F,"불량") -> 0 | BC14: =SUM(AQ14:BB14) -> 3
C15: 동양 DFORT-G104 (1*1) | D15: EA | E15: 13 | F15: 3 | H15: 3 | I15: =(F15+BC15)-(G15+H15) -> 1 | J15: =Y15 -> 12 | K15: =AN15 -> 9 | L15: =E15-J15+K15 -> 10 | M15: =SUMIFS('센터 자재 사용내역(01월)'!G:G,'센터 자재 사용내역(01월)'!E:E,'사급자재 사용내역'!C15,'센터 자재 사용내역(01월)'!F:F,"신규")+SUMIFS('센터 자재 사용내역(01월)'!G:G,'센터 자재 사용내역(01월)'!E:E,'사급자재 사용내역'!C15,'센터 자재 사용내역(01월)'!F:F,"교체") -> 0 | N15: =SUMIFS('센터 자재 사용내역(02월)'!G:G,'센터 자재 사용내역(02월)'!E:E,'사급자재 사용내역'!C15,'센터 자재 사용내역(02월)'!F:F,"신규")+SUMIFS('센터 자재 사용내역(02월)'!G:G,'센터 자재 사용내역(02월)'!E:E,'사급자재 사용내역'!C15,'센터 자재 사용내역(02월)'!F:F,"교체") -> 3 | O15: =SUMIFS('센터 자재 사용내역(03월)'!G:G,'센터 자재 사용내역(03월)'!E:E,'사급자재 사용내역'!C15,'센터 자재 사용내역(03월)'!F:F,"신규")+SUMIFS('센터 자재 사용내역(03월)'!G:G,'센터 자재 사용내역(03월)'!E:E,'사급자재 사용내역'!C15,'센터 자재 사용내역(03월)'!F:F,"교체") -> 1 | P15: =SUMIFS('센터 자재 사용내역(04월)'!G:G,'센터 자재 사용내역(04월)'!E:E,'사급자재 사용내역'!C15,'센터 자재 사용내역(04월)'!F:F,"신규")+SUMIFS('센터 자재 사용내역(04월)'!G:G,'센터 자재 사용내역(04월)'!E:E,'사급자재 사용내역'!C15,'센터 자재 사용내역(04월)'!F:F,"교체") -> 0 | Q15: =SUMIFS('센터 자재 사용내역(05월)'!G:G,'센터 자재 사용내역(05월)'!E:E,'사급자재 사용내역'!C15,'센터 자재 사용내역(05월)'!F:F,"신규")+SUMIFS('센터 자재 사용내역(05월)'!G:G,'센터 자재 사용내역(05월)'!E:E,'사급자재 사용내역'!C15,'센터 자재 사용내역(05월)'!F:F,"교체") -> 1 | R15: =SUMIFS('센터 자재 사용내역(06월)'!G:G,'센터 자재 사용내역(06월)'!E:E,'사급자재 사용내역'!C15,'센터 자재 사용내역(06월)'!F:F,"신규")+SUMIFS('센터 자재 사용내역(06월)'!G:G,'센터 자재 사용내역(06월)'!E:E,'사급자재 사용내역'!C15,'센터 자재 사용내역(06월)'!F:F,"교체") -> 3 | S15: =SUMIFS('센터 자재 사용내역(07월)'!G:G,'센터 자재 사용내역(07월)'!E:E,'사급자재 사용내역'!C15,'센터 자재 사용내역(07월)'!F:F,"신규")+SUMIFS('센터 자재 사용내역(07월)'!G:G,'센터 자재 사용내역(07월)'!E:E,'사급자재 사용내역'!C15,'센터 자재 사용내역(07월)'!F:F,"교체") -> 2 | T15: =SUMIFS('센터 자재 사용내역(08월)'!G:G,'센터 자재 사용내역(08월)'!E:E,'사급자재 사용내역'!C15,'센터 자재 사용내역(08월)'!F:F,"신규")+SUMIFS('센터 자재 사용내역(08월)'!G:G,'센터 자재 사용내역(08월)'!E:E,'사급자재 사용내역'!C15,'센터 자재 사용내역(08월)'!F:F,"교체") -> 2 | U15: =SUMIFS('센터 자재 사용내역(09월)'!G:G,'센터 자재 사용내역(09월)'!E:E,'사급자재 사용내역'!C15,'센터 자재 사용내역(09월)'!F:F,"신규")+SUMIFS('센터 자재 사용내역(09월)'!G:G,'센터 자재 사용내역(09월)'!E:E,'사급자재 사용내역'!C15,'센터 자재 사용내역(09월)'!F:F,"교체") -> 0 | V15: =SUMIFS('센터 자재 사용내역(10월)'!G:G,'센터 자재 사용내역(10월)'!E:E,'사급자재 사용내역'!C15,'센터 자재 사용내역(10월)'!F:F,"신규")+SUMIFS('센터 자재 사용내역(10월)'!G:G,'센터 자재 사용내역(10월)'!E:E,'사급자재 사용내역'!C15,'센터 자재 사용내역(10월)'!F:F,"교체") -> 0 | W15: =SUMIFS('센터 자재 사용내역(11월)'!G:G,'센터 자재 사용내역(11월)'!E:E,'사급자재 사용내역'!C15,'센터 자재 사용내역(11월)'!F:F,"신규")+SUMIFS('센터 자재 사용내역(11월)'!G:G,'센터 자재 사용내역(11월)'!E:E,'사급자재 사용내역'!C15,'센터 자재 사용내역(11월)'!F:F,"교체") -> 0 | X15: =SUMIFS('센터 자재 사용내역(12월)'!G:G,'센터 자재 사용내역(12월)'!E:E,'사급자재 사용내역'!C15,'센터 자재 사용내역(12월)'!F:F,"신규")+SUMIFS('센터 자재 사용내역(12월)'!G:G,'센터 자재 사용내역(12월)'!E:E,'사급자재 사용내역'!C15,'센터 자재 사용내역(12월)'!F:F,"교체") -> 0 | Y15: =SUM(M15:X15) -> 12 | AB15: 1 | AD15: 2 | AE15: 2 | AF15: 1 | AG15: 1 | AH15: 2 | AN15: =SUM(AB15:AM15) -> 9 | AQ15: =SUMIFS('센터 자재 사용내역(01월)'!G:G,'센터 자재 사용내역(01월)'!E:E,'사급자재 사용내역'!C15,'센터 자재 사용내역(01월)'!F:F,"불량") -> 0 | AR15: =SUMIFS('센터 자재 사용내역(02월)'!G:G,'센터 자재 사용내역(02월)'!E:E,'사급자재 사용내역'!C15,'센터 자재 사용내역(02월)'!F:F,"불량") -> 0 | AS15: =SUMIFS('센터 자재 사용내역(03월)'!G:G,'센터 자재 사용내역(03월)'!E:E,'사급자재 사용내역'!C15,'센터 자재 사용내역(03월)'!F:F,"불량") -> 0 | AT15: =SUMIFS('센터 자재 사용내역(04월)'!G:G,'센터 자재 사용내역(04월)'!E:E,'사급자재 사용내역'!C15,'센터 자재 사용내역(04월)'!F:F,"불량") -> 0 | AU15: =SUMIFS('센터 자재 사용내역(05월)'!G:G,'센터 자재 사용내역(05월)'!E:E,'사급자재 사용내역'!C15,'센터 자재 사용내역(05월)'!F:F,"불량") -> 0 | AV15: =SUMIFS('센터 자재 사용내역(06월)'!G:G,'센터 자재 사용내역(06월)'!E:E,'사급자재 사용내역'!C15,'센터 자재 사용내역(06월)'!F:F,"불량") -> 0 | AW15: =SUMIFS('센터 자재 사용내역(07월)'!G:G,'센터 자재 사용내역(07월)'!E:E,'사급자재 사용내역'!C15,'센터 자재 사용내역(07월)'!F:F,"불량") -> 0 | AX15: =SUMIFS('센터 자재 사용내역(08월)'!G:G,'센터 자재 사용내역(08월)'!E:E,'사급자재 사용내역'!C15,'센터 자재 사용내역(08월)'!F:F,"불량") -> 1 | AY15: =SUMIFS('센터 자재 사용내역(09월)'!G:G,'센터 자재 사용내역(09월)'!E:E,'사급자재 사용내역'!C15,'센터 자재 사용내역(09월)'!F:F,"불량") -> 0 | AZ15: =SUMIFS('센터 자재 사용내역(10월)'!G:G,'센터 자재 사용내역(10월)'!E:E,'사급자재 사용내역'!C15,'센터 자재 사용내역(10월)'!F:F,"불량") -> 0 | BA15: =SUMIFS('센터 자재 사용내역(11월)'!G:G,'센터 자재 사용내역(11월)'!E:E,'사급자재 사용내역'!C15,'센터 자재 사용내역(11월)'!F:F,"불량") -> 0 | BB15: =SUMIFS('센터 자재 사용내역(12월)'!G:G,'센터 자재 사용내역(12월)'!E:E,'사급자재 사용내역'!C15,'센터 자재 사용내역(12월)'!F:F,"불량") -> 0 | BC15: =SUM(AQ15:BB15) -> 1
C16: 동양 DFORT-G104 (1*2) | D16: EA | E16: 0 | F16: 0 | I16: =(F16+BC16)-(G16+H16) -> 0 | J16: =Y16 -> 0 | K16: =AN16 -> 0 | L16: =E16-J16+K16 -> 0 | M16: =SUMIFS('센터 자재 사용내역(01월)'!G:G,'센터 자재 사용내역(01월)'!E:E,'사급자재 사용내역'!C16,'센터 자재 사용내역(01월)'!F:F,"신규")+SUMIFS('센터 자재 사용내역(01월)'!G:G,'센터 자재 사용내역(01월)'!E:E,'사급자재 사용내역'!C16,'센터 자재 사용내역(01월)'!F:F,"교체") -> 0 | N16: =SUMIFS('센터 자재 사용내역(02월)'!G:G,'센터 자재 사용내역(02월)'!E:E,'사급자재 사용내역'!C16,'센터 자재 사용내역(02월)'!F:F,"신규")+SUMIFS('센터 자재 사용내역(02월)'!G:G,'센터 자재 사용내역(02월)'!E:E,'사급자재 사용내역'!C16,'센터 자재 사용내역(02월)'!F:F,"교체") -> 0 | O16: =SUMIFS('센터 자재 사용내역(03월)'!G:G,'센터 자재 사용내역(03월)'!E:E,'사급자재 사용내역'!C16,'센터 자재 사용내역(03월)'!F:F,"신규")+SUMIFS('센터 자재 사용내역(03월)'!G:G,'센터 자재 사용내역(03월)'!E:E,'사급자재 사용내역'!C16,'센터 자재 사용내역(03월)'!F:F,"교체") -> 0 | P16: =SUMIFS('센터 자재 사용내역(04월)'!G:G,'센터 자재 사용내역(04월)'!E:E,'사급자재 사용내역'!C16,'센터 자재 사용내역(04월)'!F:F,"신규")+SUMIFS('센터 자재 사용내역(04월)'!G:G,'센터 자재 사용내역(04월)'!E:E,'사급자재 사용내역'!C16,'센터 자재 사용내역(04월)'!F:F,"교체") -> 0 | Q16: =SUMIFS('센터 자재 사용내역(05월)'!G:G,'센터 자재 사용내역(05월)'!E:E,'사급자재 사용내역'!C16,'센터 자재 사용내역(05월)'!F:F,"신규")+SUMIFS('센터 자재 사용내역(05월)'!G:G,'센터 자재 사용내역(05월)'!E:E,'사급자재 사용내역'!C16,'센터 자재 사용내역(05월)'!F:F,"교체") -> 0 | R16: =SUMIFS('센터 자재 사용내역(06월)'!G:G,'센터 자재 사용내역(06월)'!E:E,'사급자재 사용내역'!C16,'센터 자재 사용내역(06월)'!F:F,"신규")+SUMIFS('센터 자재 사용내역(06월)'!G:G,'센터 자재 사용내역(06월)'!E:E,'사급자재 사용내역'!C16,'센터 자재 사용내역(06월)'!F:F,"교체") -> 0 | S16: =SUMIFS('센터 자재 사용내역(07월)'!G:G,'센터 자재 사용내역(07월)'!E:E,'사급자재 사용내역'!C16,'센터 자재 사용내역(07월)'!F:F,"신규")+SUMIFS('센터 자재 사용내역(07월)'!G:G,'센터 자재 사용내역(07월)'!E:E,'사급자재 사용내역'!C16,'센터 자재 사용내역(07월)'!F:F,"교체") -> 0 | T16: =SUMIFS('센터 자재 사용내역(08월)'!G:G,'센터 자재 사용내역(08월)'!E:E,'사급자재 사용내역'!C16,'센터 자재 사용내역(08월)'!F:F,"신규")+SUMIFS('센터 자재 사용내역(08월)'!G:G,'센터 자재 사용내역(08월)'!E:E,'사급자재 사용내역'!C16,'센터 자재 사용내역(08월)'!F:F,"교체") -> 0 | U16: =SUMIFS('센터 자재 사용내역(09월)'!G:G,'센터 자재 사용내역(09월)'!E:E,'사급자재 사용내역'!C16,'센터 자재 사용내역(09월)'!F:F,"신규")+SUMIFS('센터 자재 사용내역(09월)'!G:G,'센터 자재 사용내역(09월)'!E:E,'사급자재 사용내역'!C16,'센터 자재 사용내역(09월)'!F:F,"교체") -> 0 | V16: =SUMIFS('센터 자재 사용내역(10월)'!G:G,'센터 자재 사용내역(10월)'!E:E,'사급자재 사용내역'!C16,'센터 자재 사용내역(10월)'!F:F,"신규")+SUMIFS('센터 자재 사용내역(10월)'!G:G,'센터 자재 사용내역(10월)'!E:E,'사급자재 사용내역'!C16,'센터 자재 사용내역(10월)'!F:F,"교체") -> 0 | W16: =SUMIFS('센터 자재 사용내역(11월)'!G:G,'센터 자재 사용내역(11월)'!E:E,'사급자재 사용내역'!C16,'센터 자재 사용내역(11월)'!F:F,"신규")+SUMIFS('센터 자재 사용내역(11월)'!G:G,'센터 자재 사용내역(11월)'!E:E,'사급자재 사용내역'!C16,'센터 자재 사용내역(11월)'!F:F,"교체") -> 0 | X16: =SUMIFS('센터 자재 사용내역(12월)'!G:G,'센터 자재 사용내역(12월)'!E:E,'사급자재 사용내역'!C16,'센터 자재 사용내역(12월)'!F:F,"신규")+SUMIFS('센터 자재 사용내역(12월)'!G:G,'센터 자재 사용내역(12월)'!E:E,'사급자재 사용내역'!C16,'센터 자재 사용내역(12월)'!F:F,"교체") -> 0 | Y16: =SUM(M16:X16) -> 0 | AN16: =SUM(AB16:AM16) -> 0 | AQ16: =SUMIFS('센터 자재 사용내역(01월)'!G:G,'센터 자재 사용내역(01월)'!E:E,'사급자재 사용내역'!C16,'센터 자재 사용내역(01월)'!F:F,"불량") -> 0 | AR16: =SUMIFS('센터 자재 사용내역(02월)'!G:G,'센터 자재 사용내역(02월)'!E:E,'사급자재 사용내역'!C16,'센터 자재 사용내역(02월)'!F:F,"불량") -> 0 | AS16: =SUMIFS('센터 자재 사용내역(03월)'!G:G,'센터 자재 사용내역(03월)'!E:E,'사급자재 사용내역'!C16,'센터 자재 사용내역(03월)'!F:F,"불량") -> 0 | AT16: =SUMIFS('센터 자재 사용내역(04월)'!G:G,'센터 자재 사용내역(04월)'!E:E,'사급자재 사용내역'!C16,'센터 자재 사용내역(04월)'!F:F,"불량") -> 0 | AU16: =SUMIFS('센터 자재 사용내역(05월)'!G:G,'센터 자재 사용내역(05월)'!E:E,'사급자재 사용내역'!C16,'센터 자재 사용내역(05월)'!F:F,"불량") -> 0 | AV16: =SUMIFS('센터 자재 사용내역(06월)'!G:G,'센터 자재 사용내역(06월)'!E:E,'사급자재 사용내역'!C16,'센터 자재 사용내역(06월)'!F:F,"불량") -> 0 | AW16: =SUMIFS('센터 자재 사용내역(07월)'!G:G,'센터 자재 사용내역(07월)'!E:E,'사급자재 사용내역'!C16,'센터 자재 사용내역(07월)'!F:F,"불량") -> 0 | AX16: =SUMIFS('센터 자재 사용내역(08월)'!G:G,'센터 자재 사용내역(08월)'!E:E,'사급자재 사용내역'!C16,'센터 자재 사용내역(08월)'!F:F,"불량") -> 0 | AY16: =SUMIFS('센터 자재 사용내역(09월)'!G:G,'센터 자재 사용내역(09월)'!E:E,'사급자재 사용내역'!C16,'센터 자재 사용내역(09월)'!F:F,"불량") -> 0 | AZ16: =SUMIFS('센터 자재 사용내역(10월)'!G:G,'센터 자재 사용내역(10월)'!E:E,'사급자재 사용내역'!C16,'센터 자재 사용내역(10월)'!F:F,"불량") -> 0 | BA16: =SUMIFS('센터 자재 사용내역(11월)'!G:G,'센터 자재 사용내역(11월)'!E:E,'사급자재 사용내역'!C16,'센터 자재 사용내역(11월)'!F:F,"불량") -> 0 | BB16: =SUMIFS('센터 자재 사용내역(12월)'!G:G,'센터 자재 사용내역(12월)'!E:E,'사급자재 사용내역'!C16,'센터 자재 사용내역(12월)'!F:F,"불량") -> 0 | BC16: =SUM(AQ16:BB16) -> 0
C17: 동양 DFORT-G204 (1*1) | D17: EA | E17: 4 | F17: 1 | I17: =(F17+BC17)-(G17+H17) -> 2 | J17: =Y17 -> 6 | K17: =AN17 -> 2 | L17: =E17-J17+K17 -> 0 | M17: =SUMIFS('센터 자재 사용내역(01월)'!G:G,'센터 자재 사용내역(01월)'!E:E,'사급자재 사용내역'!C17,'센터 자재 사용내역(01월)'!F:F,"신규")+SUMIFS('센터 자재 사용내역(01월)'!G:G,'센터 자재 사용내역(01월)'!E:E,'사급자재 사용내역'!C17,'센터 자재 사용내역(01월)'!F:F,"교체") -> 2 | N17: =SUMIFS('센터 자재 사용내역(02월)'!G:G,'센터 자재 사용내역(02월)'!E:E,'사급자재 사용내역'!C17,'센터 자재 사용내역(02월)'!F:F,"신규")+SUMIFS('센터 자재 사용내역(02월)'!G:G,'센터 자재 사용내역(02월)'!E:E,'사급자재 사용내역'!C17,'센터 자재 사용내역(02월)'!F:F,"교체") -> 0 | O17: =SUMIFS('센터 자재 사용내역(03월)'!G:G,'센터 자재 사용내역(03월)'!E:E,'사급자재 사용내역'!C17,'센터 자재 사용내역(03월)'!F:F,"신규")+SUMIFS('센터 자재 사용내역(03월)'!G:G,'센터 자재 사용내역(03월)'!E:E,'사급자재 사용내역'!C17,'센터 자재 사용내역(03월)'!F:F,"교체") -> 0 | P17: =SUMIFS('센터 자재 사용내역(04월)'!G:G,'센터 자재 사용내역(04월)'!E:E,'사급자재 사용내역'!C17,'센터 자재 사용내역(04월)'!F:F,"신규")+SUMIFS('센터 자재 사용내역(04월)'!G:G,'센터 자재 사용내역(04월)'!E:E,'사급자재 사용내역'!C17,'센터 자재 사용내역(04월)'!F:F,"교체") -> 1 | Q17: =SUMIFS('센터 자재 사용내역(05월)'!G:G,'센터 자재 사용내역(05월)'!E:E,'사급자재 사용내역'!C17,'센터 자재 사용내역(05월)'!F:F,"신규")+SUMIFS('센터 자재 사용내역(05월)'!G:G,'센터 자재 사용내역(05월)'!E:E,'사급자재 사용내역'!C17,'센터 자재 사용내역(05월)'!F:F,"교체") -> 1 | R17: =SUMIFS('센터 자재 사용내역(06월)'!G:G,'센터 자재 사용내역(06월)'!E:E,'사급자재 사용내역'!C17,'센터 자재 사용내역(06월)'!F:F,"신규")+SUMIFS('센터 자재 사용내역(06월)'!G:G,'센터 자재 사용내역(06월)'!E:E,'사급자재 사용내역'!C17,'센터 자재 사용내역(06월)'!F:F,"교체") -> 0 | S17: =SUMIFS('센터 자재 사용내역(07월)'!G:G,'센터 자재 사용내역(07월)'!E:E,'사급자재 사용내역'!C17,'센터 자재 사용내역(07월)'!F:F,"신규")+SUMIFS('센터 자재 사용내역(07월)'!G:G,'센터 자재 사용내역(07월)'!E:E,'사급자재 사용내역'!C17,'센터 자재 사용내역(07월)'!F:F,"교체") -> 1 | T17: =SUMIFS('센터 자재 사용내역(08월)'!G:G,'센터 자재 사용내역(08월)'!E:E,'사급자재 사용내역'!C17,'센터 자재 사용내역(08월)'!F:F,"신규")+SUMIFS('센터 자재 사용내역(08월)'!G:G,'센터 자재 사용내역(08월)'!E:E,'사급자재 사용내역'!C17,'센터 자재 사용내역(08월)'!F:F,"교체") -> 1 | U17: =SUMIFS('센터 자재 사용내역(09월)'!G:G,'센터 자재 사용내역(09월)'!E:E,'사급자재 사용내역'!C17,'센터 자재 사용내역(09월)'!F:F,"신규")+SUMIFS('센터 자재 사용내역(09월)'!G:G,'센터 자재 사용내역(09월)'!E:E,'사급자재 사용내역'!C17,'센터 자재 사용내역(09월)'!F:F,"교체") -> 0 | V17: =SUMIFS('센터 자재 사용내역(10월)'!G:G,'센터 자재 사용내역(10월)'!E:E,'사급자재 사용내역'!C17,'센터 자재 사용내역(10월)'!F:F,"신규")+SUMIFS('센터 자재 사용내역(10월)'!G:G,'센터 자재 사용내역(10월)'!E:E,'사급자재 사용내역'!C17,'센터 자재 사용내역(10월)'!F:F,"교체") -> 0 | W17: =SUMIFS('센터 자재 사용내역(11월)'!G:G,'센터 자재 사용내역(11월)'!E:E,'사급자재 사용내역'!C17,'센터 자재 사용내역(11월)'!F:F,"신규")+SUMIFS('센터 자재 사용내역(11월)'!G:G,'센터 자재 사용내역(11월)'!E:E,'사급자재 사용내역'!C17,'센터 자재 사용내역(11월)'!F:F,"교체") -> 0 | X17: =SUMIFS('센터 자재 사용내역(12월)'!G:G,'센터 자재 사용내역(12월)'!E:E,'사급자재 사용내역'!C17,'센터 자재 사용내역(12월)'!F:F,"신규")+SUMIFS('센터 자재 사용내역(12월)'!G:G,'센터 자재 사용내역(12월)'!E:E,'사급자재 사용내역'!C17,'센터 자재 사용내역(12월)'!F:F,"교체") -> 0 | Y17: =SUM(M17:X17) -> 6 | AB17: 2 | AN17: =SUM(AB17:AM17) -> 2 | AQ17: =SUMIFS('센터 자재 사용내역(01월)'!G:G,'센터 자재 사용내역(01월)'!E:E,'사급자재 사용내역'!C17,'센터 자재 사용내역(01월)'!F:F,"불량") -> 0 | AR17: =SUMIFS('센터 자재 사용내역(02월)'!G:G,'센터 자재 사용내역(02월)'!E:E,'사급자재 사용내역'!C17,'센터 자재 사용내역(02월)'!F:F,"불량") -> 0 | AS17: =SUMIFS('센터 자재 사용내역(03월)'!G:G,'센터 자재 사용내역(03월)'!E:E,'사급자재 사용내역'!C17,'센터 자재 사용내역(03월)'!F:F,"불량") -> 0 | AT17: =SUMIFS('센터 자재 사용내역(04월)'!G:G,'센터 자재 사용내역(04월)'!E:E,'사급자재 사용내역'!C17,'센터 자재 사용내역(04월)'!F:F,"불량") -> 0 | AU17: =SUMIFS('센터 자재 사용내역(05월)'!G:G,'센터 자재 사용내역(05월)'!E:E,'사급자재 사용내역'!C17,'센터 자재 사용내역(05월)'!F:F,"불량") -> 0 | AV17: =SUMIFS('센터 자재 사용내역(06월)'!G:G,'센터 자재 사용내역(06월)'!E:E,'사급자재 사용내역'!C17,'센터 자재 사용내역(06월)'!F:F,"불량") -> 0 | AW17: =SUMIFS('센터 자재 사용내역(07월)'!G:G,'센터 자재 사용내역(07월)'!E:E,'사급자재 사용내역'!C17,'센터 자재 사용내역(07월)'!F:F,"불량") -> 0 | AX17: =SUMIFS('센터 자재 사용내역(08월)'!G:G,'센터 자재 사용내역(08월)'!E:E,'사급자재 사용내역'!C17,'센터 자재 사용내역(08월)'!F:F,"불량") -> 1 | AY17: =SUMIFS('센터 자재 사용내역(09월)'!G:G,'센터 자재 사용내역(09월)'!E:E,'사급자재 사용내역'!C17,'센터 자재 사용내역(09월)'!F:F,"불량") -> 0 | AZ17: =SUMIFS('센터 자재 사용내역(10월)'!G:G,'센터 자재 사용내역(10월)'!E:E,'사급자재 사용내역'!C17,'센터 자재 사용내역(10월)'!F:F,"불량") -> 0 | BA17: =SUMIFS('센터 자재 사용내역(11월)'!G:G,'센터 자재 사용내역(11월)'!E:E,'사급자재 사용내역'!C17,'센터 자재 사용내역(11월)'!F:F,"불량") -> 0 | BB17: =SUMIFS('센터 자재 사용내역(12월)'!G:G,'센터 자재 사용내역(12월)'!E:E,'사급자재 사용내역'!C17,'센터 자재 사용내역(12월)'!F:F,"불량") -> 0 | BC17: =SUM(AQ17:BB17) -> 1
